----------------
2025-01-07_16:41:15  --->
Error level: --Message-- 
Message: Zipfile contents for 2021
['crss2021csv/accident.csv', 'crss2021csv/cevent.csv', 'crss2021csv/crashrf.csv', 'crss2021csv/damage.csv', 'crss2021csv/distract.csv', 'crss2021csv/drimpair.csv', 'crss2021csv/driverrf.csv', 'crss2021csv/factor.csv', 'crss2021csv/maneuver.csv', 'crss2021csv/nmcrash.csv', 'crss2021csv/nmdistract.csv', 'crss2021csv/nmimpair.csv', 'crss2021csv/nmprior.csv', 'crss2021csv/parkwork.csv', 'crss2021csv/pbtype.csv', 'crss2021csv/person.csv', 'crss2021csv/personrf.csv', 'crss2021csv/pvehiclesf.csv', 'crss2021csv/safetyeq.csv', 'crss2021csv/vehicle.csv', 'crss2021csv/vehiclesf.csv', 'crss2021csv/vevent.csv', 'crss2021csv/violatn.csv', 'crss2021csv/vision.csv', 'crss2021csv/vpicdecode.csv', 'crss2021csv/vpictrailerdecode.csv', 'crss2021csv/vsoe.csv', 'crss2021csv/weather.csv']
NoneType: None
----------------
2025-01-07_16:41:18  --->
Error level: --Message-- 
Message: Raw cols accident.csv: 
['CASENUM', 'PSU', 'PSU_VAR', 'PSUSTRAT', 'REGION', 'REGIONNAME', 'URBANICITY', 'URBANICITYNAME', 'STRATUM', 'STRATUMNAME', 'PJ', 'WEIGHT', 'PEDS', 'PERNOTMVIT', 'VE_TOTAL', 'VE_FORMS', 'PVH_INVL', 'PERMVIT', 'MONTH', 'MONTHNAME', 'DAY_WEEK', 'DAY_WEEKNAME', 'WKDY_IM', 'WKDY_IMNAME', 'YEAR', 'YEARNAME', 'HOUR', 'HOURNAME', 'HOUR_IM', 'HOUR_IMNAME', 'MINUTE', 'MINUTENAME', 'MINUTE_IM', 'MINUTE_IMNAME', 'HARM_EV', 'HARM_EVNAME', 'EVENT1_IM', 'EVENT1_IMNAME', 'MAN_COLL', 'MAN_COLLNAME', 'MANCOL_IM', 'MANCOL_IMNAME', 'RELJCT1', 'RELJCT1NAME', 'RELJCT1_IM', 'RELJCT1_IMNAME', 'RELJCT2', 'RELJCT2NAME', 'RELJCT2_IM', 'RELJCT2_IMNAME', 'TYP_INT', 'TYP_INTNAME', 'REL_ROAD', 'REL_ROADNAME', 'WRK_ZONE', 'WRK_ZONENAME', 'LGT_COND', 'LGT_CONDNAME', 'LGTCON_IM', 'LGTCON_IMNAME', 'WEATHER', 'WEATHERNAME', 'WEATHR_IM', 'WEATHR_IMNAME', 'SCH_BUS', 'SCH_BUSNAME', 'INT_HWY', 'INT_HWYNAME', 'MAX_SEV', 'MAX_SEVNAME', 'MAXSEV_IM', 'MAXSEV_IMNAME', 'NUM_INJ', 'NUM_INJNAME', 'NO_INJ_IM', 'NO_INJ_IMNAME', 'ALCOHOL', 'ALCOHOLNAME', 'ALCHL_IM', 'ALCHL_IMNAME']
NoneType: None
----------------
2025-01-07_16:41:18  --->
Error level: --Message-- 
Message: Normalized cols accident.csv: 
['casenum', 'psu', 'psu_var', 'psustrat', 'region', 'regionname', 'urbanicity', 'urbanicityname', 'stratum', 'stratumname', 'pj', 'weight', 'peds', 'pernotmvit', 've_total', 've_forms', 'pvh_invl', 'permvit', 'month', 'monthname', 'day_week', 'day_weekname', 'wkdy_im', 'wkdy_imname', 'year', 'yearname', 'hour', 'hourname', 'hour_im', 'hour_imname', 'minute', 'minutename', 'minute_im', 'minute_imname', 'harm_ev', 'harm_evname', 'event1_im', 'event1_imname', 'man_coll', 'man_collname', 'mancol_im', 'mancol_imname', 'reljct1', 'reljct1name', 'reljct1_im', 'reljct1_imname', 'reljct2', 'reljct2name', 'reljct2_im', 'reljct2_imname', 'typ_int', 'typ_intname', 'rel_road', 'rel_roadname', 'wrk_zone', 'wrk_zonename', 'lgt_cond', 'lgt_condname', 'lgtcon_im', 'lgtcon_imname', 'weather', 'weathername', 'weathr_im', 'weathr_imname', 'sch_bus', 'sch_busname', 'int_hwy', 'int_hwyname', 'max_sev', 'max_sevname', 'maxsev_im', 'maxsev_imname', 'num_inj', 'num_injname', 'no_inj_im', 'no_inj_imname', 'alcohol', 'alcoholname', 'alchl_im', 'alchl_imname']
NoneType: None
----------------
2025-01-07_16:41:18  --->
Error level: --Message-- 
Message: Renamed cols accident.csv: 
['case_num', 'psu', 'psu_var', 'psustrat', 'region', 'regionname', 'urbancity', 'urbanicityname', 'stratum', 'stratumname', 'pj', 'weight', 'pedestrian', 'notin_veh', 'vehicles', 'moving', 'not_moving', 'occupants', 'month', 'monthname', 'day_week', 'day_weekname', 'wkdy_im', 'wkdy_imname', 'year', 'yearname', 'hour', 'hourname', 'hour_im', 'hour_imname', 'minute', 'minutename', 'minute_im', 'minute_imname', 'harm_ev', 'harm_evname', 'event1_im', 'event1_imname', 'collision', 'man_collname', 'mancol_im', 'mancol_imname', 'reljct1', 'reljct1name', 'reljct1_im', 'reljct1_imname', 'reljct2', 'reljct2name', 'related_junct', 'reljct2_imname', 'intersection', 'typ_intname', 'roadway', 'rel_roadname', 'workzone', 'wrk_zonename', 'lgt_cond', 'lgt_condname', 'lighting', 'lgtcon_imname', 'weather', 'weathername', 'weathr_im', 'weathr_imname', 'sch_bus', 'sch_busname', 'highway', 'int_hwyname', 'max_sev', 'max_sevname', 'max_injury', 'maxsev_imname', 'num_inj', 'num_injname', 'injuries', 'no_inj_imname', 'alcohol', 'alcoholname', 'alchl_im', 'alchl_imname']
NoneType: None
----------------
2025-01-07_16:41:47  --->
Error level: ***ALERT!*** 
Message: Loading fact_accident failed!
1062 (23000): Duplicate entry '202102916823' for key 'fact_accident.PRIMARY'
Traceback (most recent call last):
  File "c:\Users\cojac\Projects\crss\src\main.py", line 161, in crss_etl
    db_curs.executemany(load_ready, crss_df.values.tolist())
  File "C:\Users\cojac\AppData\Local\Packages\PythonSoftwareFoundation.Python.3.10_qbz5n2kfra8p0\LocalCache\local-packages\Python310\site-packages\mysql\connector\cursor.py", line 723, in executemany
    return self.execute(stmt)
  File "C:\Users\cojac\AppData\Local\Packages\PythonSoftwareFoundation.Python.3.10_qbz5n2kfra8p0\LocalCache\local-packages\Python310\site-packages\mysql\connector\cursor.py", line 617, in execute
    self._handle_result(self._connection.cmd_query(stmt))
  File "C:\Users\cojac\AppData\Local\Packages\PythonSoftwareFoundation.Python.3.10_qbz5n2kfra8p0\LocalCache\local-packages\Python310\site-packages\mysql\connector\connection.py", line 1046, in cmd_query
    result = self._handle_result(self._send_cmd(ServerCmd.QUERY, query))
  File "C:\Users\cojac\AppData\Local\Packages\PythonSoftwareFoundation.Python.3.10_qbz5n2kfra8p0\LocalCache\local-packages\Python310\site-packages\mysql\connector\connection.py", line 824, in _handle_result
    raise get_exception(packet)
mysql.connector.errors.IntegrityError: 1062 (23000): Duplicate entry '202102916823' for key 'fact_accident.PRIMARY'
----------------
2025-01-07_16:51:42  --->
Error level: --Message-- 
Message: Zipfile contents for 2021
['crss2021csv/accident.csv', 'crss2021csv/cevent.csv', 'crss2021csv/crashrf.csv', 'crss2021csv/damage.csv', 'crss2021csv/distract.csv', 'crss2021csv/drimpair.csv', 'crss2021csv/driverrf.csv', 'crss2021csv/factor.csv', 'crss2021csv/maneuver.csv', 'crss2021csv/nmcrash.csv', 'crss2021csv/nmdistract.csv', 'crss2021csv/nmimpair.csv', 'crss2021csv/nmprior.csv', 'crss2021csv/parkwork.csv', 'crss2021csv/pbtype.csv', 'crss2021csv/person.csv', 'crss2021csv/personrf.csv', 'crss2021csv/pvehiclesf.csv', 'crss2021csv/safetyeq.csv', 'crss2021csv/vehicle.csv', 'crss2021csv/vehiclesf.csv', 'crss2021csv/vevent.csv', 'crss2021csv/violatn.csv', 'crss2021csv/vision.csv', 'crss2021csv/vpicdecode.csv', 'crss2021csv/vpictrailerdecode.csv', 'crss2021csv/vsoe.csv', 'crss2021csv/weather.csv']
NoneType: None
----------------
2025-01-07_16:51:45  --->
Error level: --Message-- 
Message: Raw cols accident.csv: 
['CASENUM', 'PSU', 'PSU_VAR', 'PSUSTRAT', 'REGION', 'REGIONNAME', 'URBANICITY', 'URBANICITYNAME', 'STRATUM', 'STRATUMNAME', 'PJ', 'WEIGHT', 'PEDS', 'PERNOTMVIT', 'VE_TOTAL', 'VE_FORMS', 'PVH_INVL', 'PERMVIT', 'MONTH', 'MONTHNAME', 'DAY_WEEK', 'DAY_WEEKNAME', 'WKDY_IM', 'WKDY_IMNAME', 'YEAR', 'YEARNAME', 'HOUR', 'HOURNAME', 'HOUR_IM', 'HOUR_IMNAME', 'MINUTE', 'MINUTENAME', 'MINUTE_IM', 'MINUTE_IMNAME', 'HARM_EV', 'HARM_EVNAME', 'EVENT1_IM', 'EVENT1_IMNAME', 'MAN_COLL', 'MAN_COLLNAME', 'MANCOL_IM', 'MANCOL_IMNAME', 'RELJCT1', 'RELJCT1NAME', 'RELJCT1_IM', 'RELJCT1_IMNAME', 'RELJCT2', 'RELJCT2NAME', 'RELJCT2_IM', 'RELJCT2_IMNAME', 'TYP_INT', 'TYP_INTNAME', 'REL_ROAD', 'REL_ROADNAME', 'WRK_ZONE', 'WRK_ZONENAME', 'LGT_COND', 'LGT_CONDNAME', 'LGTCON_IM', 'LGTCON_IMNAME', 'WEATHER', 'WEATHERNAME', 'WEATHR_IM', 'WEATHR_IMNAME', 'SCH_BUS', 'SCH_BUSNAME', 'INT_HWY', 'INT_HWYNAME', 'MAX_SEV', 'MAX_SEVNAME', 'MAXSEV_IM', 'MAXSEV_IMNAME', 'NUM_INJ', 'NUM_INJNAME', 'NO_INJ_IM', 'NO_INJ_IMNAME', 'ALCOHOL', 'ALCOHOLNAME', 'ALCHL_IM', 'ALCHL_IMNAME']
NoneType: None
----------------
2025-01-07_16:51:45  --->
Error level: --Message-- 
Message: Normalized cols accident.csv: 
['casenum', 'psu', 'psu_var', 'psustrat', 'region', 'regionname', 'urbanicity', 'urbanicityname', 'stratum', 'stratumname', 'pj', 'weight', 'peds', 'pernotmvit', 've_total', 've_forms', 'pvh_invl', 'permvit', 'month', 'monthname', 'day_week', 'day_weekname', 'wkdy_im', 'wkdy_imname', 'year', 'yearname', 'hour', 'hourname', 'hour_im', 'hour_imname', 'minute', 'minutename', 'minute_im', 'minute_imname', 'harm_ev', 'harm_evname', 'event1_im', 'event1_imname', 'man_coll', 'man_collname', 'mancol_im', 'mancol_imname', 'reljct1', 'reljct1name', 'reljct1_im', 'reljct1_imname', 'reljct2', 'reljct2name', 'reljct2_im', 'reljct2_imname', 'typ_int', 'typ_intname', 'rel_road', 'rel_roadname', 'wrk_zone', 'wrk_zonename', 'lgt_cond', 'lgt_condname', 'lgtcon_im', 'lgtcon_imname', 'weather', 'weathername', 'weathr_im', 'weathr_imname', 'sch_bus', 'sch_busname', 'int_hwy', 'int_hwyname', 'max_sev', 'max_sevname', 'maxsev_im', 'maxsev_imname', 'num_inj', 'num_injname', 'no_inj_im', 'no_inj_imname', 'alcohol', 'alcoholname', 'alchl_im', 'alchl_imname']
NoneType: None
----------------
2025-01-07_16:51:45  --->
Error level: --Message-- 
Message: Renamed cols accident.csv: 
['case_num', 'psu', 'psu_var', 'psustrat', 'region', 'regionname', 'urbancity', 'urbanicityname', 'stratum', 'stratumname', 'pj', 'weight', 'pedestrian', 'notin_veh', 'vehicles', 'moving', 'not_moving', 'occupants', 'month', 'monthname', 'day_week', 'day_weekname', 'wkdy_im', 'wkdy_imname', 'year', 'yearname', 'hour', 'hourname', 'hour_im', 'hour_imname', 'minute', 'minutename', 'minute_im', 'minute_imname', 'harm_ev', 'harm_evname', 'event1_im', 'event1_imname', 'collision', 'man_collname', 'mancol_im', 'mancol_imname', 'reljct1', 'reljct1name', 'reljct1_im', 'reljct1_imname', 'reljct2', 'reljct2name', 'related_junct', 'reljct2_imname', 'intersection', 'typ_intname', 'roadway', 'rel_roadname', 'workzone', 'wrk_zonename', 'lgt_cond', 'lgt_condname', 'lighting', 'lgtcon_imname', 'weather', 'weathername', 'weathr_im', 'weathr_imname', 'sch_bus', 'sch_busname', 'highway', 'int_hwyname', 'max_sev', 'max_sevname', 'max_injury', 'maxsev_imname', 'num_inj', 'num_injname', 'injuries', 'no_inj_imname', 'alcohol', 'alcoholname', 'alchl_im', 'alchl_imname']
NoneType: None
----------------
2025-01-07_16:52:05  --->
Error level: ***ALERT!*** 
Message: Loading Phase for year 2021, table fact_accident failed to load
[Errno 2] No such file or directory: 'C:\\Users\\cojac/Projects/crss/data/readydata/ACCIDENT.CSV'
Traceback (most recent call last):
  File "c:\Users\cojac\Projects\crss\src\main.py", line 139, in crss_etl
    crss_df = pandas.read_csv(crss[key]["ready_dir"])
  File "C:\Users\cojac\AppData\Local\Packages\PythonSoftwareFoundation.Python.3.10_qbz5n2kfra8p0\LocalCache\local-packages\Python310\site-packages\pandas\io\parsers\readers.py", line 1026, in read_csv
    return _read(filepath_or_buffer, kwds)
  File "C:\Users\cojac\AppData\Local\Packages\PythonSoftwareFoundation.Python.3.10_qbz5n2kfra8p0\LocalCache\local-packages\Python310\site-packages\pandas\io\parsers\readers.py", line 620, in _read
    parser = TextFileReader(filepath_or_buffer, **kwds)
  File "C:\Users\cojac\AppData\Local\Packages\PythonSoftwareFoundation.Python.3.10_qbz5n2kfra8p0\LocalCache\local-packages\Python310\site-packages\pandas\io\parsers\readers.py", line 1620, in __init__
    self._engine = self._make_engine(f, self.engine)
  File "C:\Users\cojac\AppData\Local\Packages\PythonSoftwareFoundation.Python.3.10_qbz5n2kfra8p0\LocalCache\local-packages\Python310\site-packages\pandas\io\parsers\readers.py", line 1880, in _make_engine
    self.handles = get_handle(
  File "C:\Users\cojac\AppData\Local\Packages\PythonSoftwareFoundation.Python.3.10_qbz5n2kfra8p0\LocalCache\local-packages\Python310\site-packages\pandas\io\common.py", line 873, in get_handle
    handle = open(
FileNotFoundError: [Errno 2] No such file or directory: 'C:\\Users\\cojac/Projects/crss/data/readydata/ACCIDENT.CSV'
----------------
2025-01-07_17:10:12  --->
Error level: --Message-- 
Message: Zipfile contents for 2021
['crss2021csv/accident.csv', 'crss2021csv/cevent.csv', 'crss2021csv/crashrf.csv', 'crss2021csv/damage.csv', 'crss2021csv/distract.csv', 'crss2021csv/drimpair.csv', 'crss2021csv/driverrf.csv', 'crss2021csv/factor.csv', 'crss2021csv/maneuver.csv', 'crss2021csv/nmcrash.csv', 'crss2021csv/nmdistract.csv', 'crss2021csv/nmimpair.csv', 'crss2021csv/nmprior.csv', 'crss2021csv/parkwork.csv', 'crss2021csv/pbtype.csv', 'crss2021csv/person.csv', 'crss2021csv/personrf.csv', 'crss2021csv/pvehiclesf.csv', 'crss2021csv/safetyeq.csv', 'crss2021csv/vehicle.csv', 'crss2021csv/vehiclesf.csv', 'crss2021csv/vevent.csv', 'crss2021csv/violatn.csv', 'crss2021csv/vision.csv', 'crss2021csv/vpicdecode.csv', 'crss2021csv/vpictrailerdecode.csv', 'crss2021csv/vsoe.csv', 'crss2021csv/weather.csv']
NoneType: None
----------------
2025-01-07_17:10:15  --->
Error level: --Message-- 
Message: Raw cols accident.csv: 
['CASENUM', 'PSU', 'PSU_VAR', 'PSUSTRAT', 'REGION', 'REGIONNAME', 'URBANICITY', 'URBANICITYNAME', 'STRATUM', 'STRATUMNAME', 'PJ', 'WEIGHT', 'PEDS', 'PERNOTMVIT', 'VE_TOTAL', 'VE_FORMS', 'PVH_INVL', 'PERMVIT', 'MONTH', 'MONTHNAME', 'DAY_WEEK', 'DAY_WEEKNAME', 'WKDY_IM', 'WKDY_IMNAME', 'YEAR', 'YEARNAME', 'HOUR', 'HOURNAME', 'HOUR_IM', 'HOUR_IMNAME', 'MINUTE', 'MINUTENAME', 'MINUTE_IM', 'MINUTE_IMNAME', 'HARM_EV', 'HARM_EVNAME', 'EVENT1_IM', 'EVENT1_IMNAME', 'MAN_COLL', 'MAN_COLLNAME', 'MANCOL_IM', 'MANCOL_IMNAME', 'RELJCT1', 'RELJCT1NAME', 'RELJCT1_IM', 'RELJCT1_IMNAME', 'RELJCT2', 'RELJCT2NAME', 'RELJCT2_IM', 'RELJCT2_IMNAME', 'TYP_INT', 'TYP_INTNAME', 'REL_ROAD', 'REL_ROADNAME', 'WRK_ZONE', 'WRK_ZONENAME', 'LGT_COND', 'LGT_CONDNAME', 'LGTCON_IM', 'LGTCON_IMNAME', 'WEATHER', 'WEATHERNAME', 'WEATHR_IM', 'WEATHR_IMNAME', 'SCH_BUS', 'SCH_BUSNAME', 'INT_HWY', 'INT_HWYNAME', 'MAX_SEV', 'MAX_SEVNAME', 'MAXSEV_IM', 'MAXSEV_IMNAME', 'NUM_INJ', 'NUM_INJNAME', 'NO_INJ_IM', 'NO_INJ_IMNAME', 'ALCOHOL', 'ALCOHOLNAME', 'ALCHL_IM', 'ALCHL_IMNAME']
NoneType: None
----------------
2025-01-07_17:10:15  --->
Error level: --Message-- 
Message: Normalized cols accident.csv: 
['casenum', 'psu', 'psu_var', 'psustrat', 'region', 'regionname', 'urbanicity', 'urbanicityname', 'stratum', 'stratumname', 'pj', 'weight', 'peds', 'pernotmvit', 've_total', 've_forms', 'pvh_invl', 'permvit', 'month', 'monthname', 'day_week', 'day_weekname', 'wkdy_im', 'wkdy_imname', 'year', 'yearname', 'hour', 'hourname', 'hour_im', 'hour_imname', 'minute', 'minutename', 'minute_im', 'minute_imname', 'harm_ev', 'harm_evname', 'event1_im', 'event1_imname', 'man_coll', 'man_collname', 'mancol_im', 'mancol_imname', 'reljct1', 'reljct1name', 'reljct1_im', 'reljct1_imname', 'reljct2', 'reljct2name', 'reljct2_im', 'reljct2_imname', 'typ_int', 'typ_intname', 'rel_road', 'rel_roadname', 'wrk_zone', 'wrk_zonename', 'lgt_cond', 'lgt_condname', 'lgtcon_im', 'lgtcon_imname', 'weather', 'weathername', 'weathr_im', 'weathr_imname', 'sch_bus', 'sch_busname', 'int_hwy', 'int_hwyname', 'max_sev', 'max_sevname', 'maxsev_im', 'maxsev_imname', 'num_inj', 'num_injname', 'no_inj_im', 'no_inj_imname', 'alcohol', 'alcoholname', 'alchl_im', 'alchl_imname']
NoneType: None
----------------
2025-01-07_17:10:15  --->
Error level: --Message-- 
Message: Renamed cols accident.csv: 
['case_num', 'psu', 'psu_var', 'psustrat', 'region', 'regionname', 'urbancity', 'urbanicityname', 'stratum', 'stratumname', 'pj', 'weight', 'pedestrian', 'notin_veh', 'vehicles', 'moving', 'not_moving', 'occupants', 'month', 'monthname', 'day_week', 'day_weekname', 'wkdy_im', 'wkdy_imname', 'year', 'yearname', 'hour', 'hourname', 'hour_im', 'hour_imname', 'minute', 'minutename', 'minute_im', 'minute_imname', 'harm_ev', 'harm_evname', 'event1_im', 'event1_imname', 'collision', 'man_collname', 'mancol_im', 'mancol_imname', 'reljct1', 'reljct1name', 'reljct1_im', 'reljct1_imname', 'reljct2', 'reljct2name', 'related_junct', 'reljct2_imname', 'intersection', 'typ_intname', 'roadway', 'rel_roadname', 'workzone', 'wrk_zonename', 'lgt_cond', 'lgt_condname', 'lighting', 'lgtcon_imname', 'weather', 'weathername', 'weathr_im', 'weathr_imname', 'sch_bus', 'sch_busname', 'highway', 'int_hwyname', 'max_sev', 'max_sevname', 'max_injury', 'maxsev_imname', 'num_inj', 'num_injname', 'injuries', 'no_inj_imname', 'alcohol', 'alcoholname', 'alchl_im', 'alchl_imname']
NoneType: None
----------------
2025-01-07_17:12:06  --->
Error level: ***ALERT!*** 
Message: ETL process:
<class 'Exception'>
Traceback (most recent call last):
  File "c:\Users\cojac\Projects\crss\src\main.py", line 176, in crss_etl
    os.rename(src=target_file, dst=archive_file)
FileNotFoundError: [WinError 2] The system cannot find the file specified: 'C:\\Users\\cojac/Projects/crss/data/readydata/C' -> 'C:\\Users\\cojac/Projects/crss/data/archivedata/2021C'
----------------
2025-01-07_17:22:00  --->
Error level: --Message-- 
Message: Zipfile contents for 2021
['crss2021csv/accident.csv', 'crss2021csv/cevent.csv', 'crss2021csv/crashrf.csv', 'crss2021csv/damage.csv', 'crss2021csv/distract.csv', 'crss2021csv/drimpair.csv', 'crss2021csv/driverrf.csv', 'crss2021csv/factor.csv', 'crss2021csv/maneuver.csv', 'crss2021csv/nmcrash.csv', 'crss2021csv/nmdistract.csv', 'crss2021csv/nmimpair.csv', 'crss2021csv/nmprior.csv', 'crss2021csv/parkwork.csv', 'crss2021csv/pbtype.csv', 'crss2021csv/person.csv', 'crss2021csv/personrf.csv', 'crss2021csv/pvehiclesf.csv', 'crss2021csv/safetyeq.csv', 'crss2021csv/vehicle.csv', 'crss2021csv/vehiclesf.csv', 'crss2021csv/vevent.csv', 'crss2021csv/violatn.csv', 'crss2021csv/vision.csv', 'crss2021csv/vpicdecode.csv', 'crss2021csv/vpictrailerdecode.csv', 'crss2021csv/vsoe.csv', 'crss2021csv/weather.csv']
NoneType: None
----------------
2025-01-07_17:22:04  --->
Error level: --Message-- 
Message: Raw cols accident.csv: 
['CASENUM', 'PSU', 'PSU_VAR', 'PSUSTRAT', 'REGION', 'REGIONNAME', 'URBANICITY', 'URBANICITYNAME', 'STRATUM', 'STRATUMNAME', 'PJ', 'WEIGHT', 'PEDS', 'PERNOTMVIT', 'VE_TOTAL', 'VE_FORMS', 'PVH_INVL', 'PERMVIT', 'MONTH', 'MONTHNAME', 'DAY_WEEK', 'DAY_WEEKNAME', 'WKDY_IM', 'WKDY_IMNAME', 'YEAR', 'YEARNAME', 'HOUR', 'HOURNAME', 'HOUR_IM', 'HOUR_IMNAME', 'MINUTE', 'MINUTENAME', 'MINUTE_IM', 'MINUTE_IMNAME', 'HARM_EV', 'HARM_EVNAME', 'EVENT1_IM', 'EVENT1_IMNAME', 'MAN_COLL', 'MAN_COLLNAME', 'MANCOL_IM', 'MANCOL_IMNAME', 'RELJCT1', 'RELJCT1NAME', 'RELJCT1_IM', 'RELJCT1_IMNAME', 'RELJCT2', 'RELJCT2NAME', 'RELJCT2_IM', 'RELJCT2_IMNAME', 'TYP_INT', 'TYP_INTNAME', 'REL_ROAD', 'REL_ROADNAME', 'WRK_ZONE', 'WRK_ZONENAME', 'LGT_COND', 'LGT_CONDNAME', 'LGTCON_IM', 'LGTCON_IMNAME', 'WEATHER', 'WEATHERNAME', 'WEATHR_IM', 'WEATHR_IMNAME', 'SCH_BUS', 'SCH_BUSNAME', 'INT_HWY', 'INT_HWYNAME', 'MAX_SEV', 'MAX_SEVNAME', 'MAXSEV_IM', 'MAXSEV_IMNAME', 'NUM_INJ', 'NUM_INJNAME', 'NO_INJ_IM', 'NO_INJ_IMNAME', 'ALCOHOL', 'ALCOHOLNAME', 'ALCHL_IM', 'ALCHL_IMNAME']
NoneType: None
----------------
2025-01-07_17:22:04  --->
Error level: --Message-- 
Message: Normalized cols accident.csv: 
['casenum', 'psu', 'psu_var', 'psustrat', 'region', 'regionname', 'urbanicity', 'urbanicityname', 'stratum', 'stratumname', 'pj', 'weight', 'peds', 'pernotmvit', 've_total', 've_forms', 'pvh_invl', 'permvit', 'month', 'monthname', 'day_week', 'day_weekname', 'wkdy_im', 'wkdy_imname', 'year', 'yearname', 'hour', 'hourname', 'hour_im', 'hour_imname', 'minute', 'minutename', 'minute_im', 'minute_imname', 'harm_ev', 'harm_evname', 'event1_im', 'event1_imname', 'man_coll', 'man_collname', 'mancol_im', 'mancol_imname', 'reljct1', 'reljct1name', 'reljct1_im', 'reljct1_imname', 'reljct2', 'reljct2name', 'reljct2_im', 'reljct2_imname', 'typ_int', 'typ_intname', 'rel_road', 'rel_roadname', 'wrk_zone', 'wrk_zonename', 'lgt_cond', 'lgt_condname', 'lgtcon_im', 'lgtcon_imname', 'weather', 'weathername', 'weathr_im', 'weathr_imname', 'sch_bus', 'sch_busname', 'int_hwy', 'int_hwyname', 'max_sev', 'max_sevname', 'maxsev_im', 'maxsev_imname', 'num_inj', 'num_injname', 'no_inj_im', 'no_inj_imname', 'alcohol', 'alcoholname', 'alchl_im', 'alchl_imname']
NoneType: None
----------------
2025-01-07_17:22:04  --->
Error level: --Message-- 
Message: Renamed cols accident.csv: 
['case_num', 'psu', 'psu_var', 'psustrat', 'region', 'regionname', 'urbancity', 'urbanicityname', 'stratum', 'stratumname', 'pj', 'weight', 'pedestrian', 'notin_veh', 'vehicles', 'moving', 'not_moving', 'occupants', 'month', 'monthname', 'day_week', 'day_weekname', 'wkdy_im', 'wkdy_imname', 'year', 'yearname', 'hour', 'hourname', 'hour_im', 'hour_imname', 'minute', 'minutename', 'minute_im', 'minute_imname', 'harm_ev', 'harm_evname', 'event1_im', 'event1_imname', 'collision', 'man_collname', 'mancol_im', 'mancol_imname', 'reljct1', 'reljct1name', 'reljct1_im', 'reljct1_imname', 'reljct2', 'reljct2name', 'related_junct', 'reljct2_imname', 'intersection', 'typ_intname', 'roadway', 'rel_roadname', 'workzone', 'wrk_zonename', 'lgt_cond', 'lgt_condname', 'lighting', 'lgtcon_imname', 'weather', 'weathername', 'weathr_im', 'weathr_imname', 'sch_bus', 'sch_busname', 'highway', 'int_hwyname', 'max_sev', 'max_sevname', 'max_injury', 'maxsev_imname', 'num_inj', 'num_injname', 'injuries', 'no_inj_imname', 'alcohol', 'alcoholname', 'alchl_im', 'alchl_imname']
NoneType: None
----------------
2025-01-07_17:24:25  --->
Error level: ***ALERT!*** 
Message: ETL process:
<class 'Exception'>
Traceback (most recent call last):
  File "c:\Users\cojac\Projects\crss\src\main.py", line 176, in crss_etl
    os.rename(src=target_file, dst=archive_file)
FileNotFoundError: [WinError 2] The system cannot find the file specified: 'C:\\Users\\cojac/Projects/crss/data/readydata/C' -> 'C:\\Users\\cojac/Projects/crss/data/archivedata/2021C'
----------------
2025-01-07_17:34:10  --->
Error level: --Message-- 
Message: Zipfile contents for 2016
['accident.csv', 'cevent.csv', 'damage.csv', 'distract.csv', 'drimpair.csv', 'factor.csv', 'maneuver.csv', 'nmcrash.csv', 'nmimpair.csv', 'nmprior.csv', 'parkwork.csv', 'pbtype.csv', 'person.csv', 'safetyeq.csv', 'vehicle.csv', 'vevent.csv', 'violatn.csv', 'vision.csv', 'vpicdecode.csv', 'vpictrailerdecode.csv', 'vsoe.csv']
NoneType: None
----------------
2025-01-07_17:34:11  --->
Error level: --Message-- 
Message: Raw cols accident.csv: 
['CASENUM', 'PSU', 'PJ', 'STRATUM', 'VE_TOTAL', 'VE_FORMS', 'PVH_INVL', 'PEDS', 'PERMVIT', 'PERNOTMVIT', 'NUM_INJ', 'MONTH', 'YEAR', 'DAY_WEEK', 'HOUR', 'MINUTE', 'HARM_EV', 'ALCOHOL', 'MAX_SEV', 'MAN_COLL', 'RELJCT1', 'RELJCT2', 'TYP_INT', 'WRK_ZONE', 'REL_ROAD', 'LGT_COND', 'WEATHER1', 'WEATHER2', 'WEATHER', 'SCH_BUS', 'INT_HWY', 'CF1', 'CF2', 'CF3', 'WKDY_IM', 'HOUR_IM', 'MINUTE_IM', 'EVENT1_IM', 'MANCOL_IM', 'RELJCT1_IM', 'RELJCT2_IM', 'LGTCON_IM', 'WEATHR_IM', 'MAXSEV_IM', 'NO_INJ_IM', 'ALCHL_IM', 'URBANICITY', 'REGION', 'PSUSTRAT', 'PSU_VAR', 'WEIGHT']
NoneType: None
----------------
2025-01-07_17:34:11  --->
Error level: --Message-- 
Message: Normalized cols accident.csv: 
['casenum', 'psu', 'pj', 'stratum', 've_total', 've_forms', 'pvh_invl', 'peds', 'permvit', 'pernotmvit', 'num_inj', 'month', 'year', 'day_week', 'hour', 'minute', 'harm_ev', 'alcohol', 'max_sev', 'man_coll', 'reljct1', 'reljct2', 'typ_int', 'wrk_zone', 'rel_road', 'lgt_cond', 'weather1', 'weather2', 'weather', 'sch_bus', 'int_hwy', 'cf1', 'cf2', 'cf3', 'wkdy_im', 'hour_im', 'minute_im', 'event1_im', 'mancol_im', 'reljct1_im', 'reljct2_im', 'lgtcon_im', 'weathr_im', 'maxsev_im', 'no_inj_im', 'alchl_im', 'urbanicity', 'region', 'psustrat', 'psu_var', 'weight']
NoneType: None
----------------
2025-01-07_17:34:11  --->
Error level: --Message-- 
Message: Renamed cols accident.csv: 
['case_num', 'psu', 'pj', 'stratum', 'vehicles', 'moving', 'not_moving', 'pedestrian', 'occupants', 'notin_veh', 'num_inj', 'month', 'year', 'day_week', 'hour', 'minute', 'harm_ev', 'alcohol', 'max_sev', 'collision', 'reljct1', 'reljct2', 'intersection', 'workzone', 'roadway', 'lgt_cond', 'weather', 'weather2', 'weather', 'sch_bus', 'highway', 'cf1', 'cf2', 'cf3', 'wkdy_im', 'hour_im', 'minute_im', 'event1_im', 'mancol_im', 'reljct1_im', 'related_junct', 'lighting', 'weathr_im', 'max_injury', 'injuries', 'alchl_im', 'urbancity', 'region', 'psustrat', 'psu_var', 'weight']
NoneType: None
----------------
2025-01-07_17:34:11  --->
Error level: --Message-- 
Message: Duplicate columns detected
['weather']
NoneType: None
----------------
2025-01-07_17:35:31  --->
Error level: ***ALERT!*** 
Message: Could not move files
<class 'Exception'>
NoneType: None
----------------
2025-01-07_17:35:31  --->
Error level: ***ALERT!*** 
Message: Could not move files
<class 'Exception'>
NoneType: None
----------------
2025-01-07_17:35:31  --->
Error level: ***ALERT!*** 
Message: Could not move files
<class 'Exception'>
NoneType: None
----------------
2025-01-07_17:35:45  --->
Error level: --Message-- 
Message: Zipfile contents for 2017
['accident.csv', 'cevent.csv', 'damage.csv', 'distract.csv', 'drimpair.csv', 'factor.csv', 'maneuver.csv', 'nmcrash.csv', 'nmimpair.csv', 'nmprior.csv', 'parkwork.csv', 'pbtype.csv', 'person.csv', 'safetyeq.csv', 'vehicle.csv', 'vevent.csv', 'violatn.csv', 'vision.csv', 'vpicdecode.csv', 'vpictrailerdecode.csv', 'vsoe.csv']
NoneType: None
----------------
2025-01-07_17:35:46  --->
Error level: --Message-- 
Message: Raw cols accident.csv: 
['CASENUM', 'REGION', 'PSU', 'PJ', 'PSU_VAR', 'URBANICITY', 'STRATUM', 'VE_TOTAL', 'VE_FORMS', 'PVH_INVL', 'PEDS', 'PERMVIT', 'PERNOTMVIT', 'NUM_INJ', 'MONTH', 'YEAR', 'DAY_WEEK', 'HOUR', 'MINUTE', 'HARM_EV', 'ALCOHOL', 'MAX_SEV', 'MAN_COLL', 'RELJCT1', 'RELJCT2', 'TYP_INT', 'WRK_ZONE', 'REL_ROAD', 'LGT_COND', 'WEATHER1', 'WEATHER2', 'WEATHER', 'SCH_BUS', 'INT_HWY', 'CF1', 'CF2', 'CF3', 'WKDY_IM', 'HOUR_IM', 'MINUTE_IM', 'EVENT1_IM', 'MANCOL_IM', 'RELJCT1_IM', 'RELJCT2_IM', 'LGTCON_IM', 'WEATHR_IM', 'MAXSEV_IM', 'NO_INJ_IM', 'ALCHL_IM', 'PSUSTRAT', 'WEIGHT']
NoneType: None
----------------
2025-01-07_17:35:46  --->
Error level: --Message-- 
Message: Normalized cols accident.csv: 
['casenum', 'region', 'psu', 'pj', 'psu_var', 'urbanicity', 'stratum', 've_total', 've_forms', 'pvh_invl', 'peds', 'permvit', 'pernotmvit', 'num_inj', 'month', 'year', 'day_week', 'hour', 'minute', 'harm_ev', 'alcohol', 'max_sev', 'man_coll', 'reljct1', 'reljct2', 'typ_int', 'wrk_zone', 'rel_road', 'lgt_cond', 'weather1', 'weather2', 'weather', 'sch_bus', 'int_hwy', 'cf1', 'cf2', 'cf3', 'wkdy_im', 'hour_im', 'minute_im', 'event1_im', 'mancol_im', 'reljct1_im', 'reljct2_im', 'lgtcon_im', 'weathr_im', 'maxsev_im', 'no_inj_im', 'alchl_im', 'psustrat', 'weight']
NoneType: None
----------------
2025-01-07_17:35:46  --->
Error level: --Message-- 
Message: Renamed cols accident.csv: 
['case_num', 'region', 'psu', 'pj', 'psu_var', 'urbancity', 'stratum', 'vehicles', 'moving', 'not_moving', 'pedestrian', 'occupants', 'notin_veh', 'num_inj', 'month', 'year', 'day_week', 'hour', 'minute', 'harm_ev', 'alcohol', 'max_sev', 'collision', 'reljct1', 'reljct2', 'intersection', 'workzone', 'roadway', 'lgt_cond', 'weather', 'weather2', 'weather', 'sch_bus', 'highway', 'cf1', 'cf2', 'cf3', 'wkdy_im', 'hour_im', 'minute_im', 'event1_im', 'mancol_im', 'reljct1_im', 'related_junct', 'lighting', 'weathr_im', 'max_injury', 'injuries', 'alchl_im', 'psustrat', 'weight']
NoneType: None
----------------
2025-01-07_17:35:46  --->
Error level: --Message-- 
Message: Duplicate columns detected
['weather']
NoneType: None
----------------
2025-01-07_17:37:36  --->
Error level: ***ALERT!*** 
Message: Could not move files
<class 'Exception'>
NoneType: None
----------------
2025-01-07_17:37:36  --->
Error level: ***ALERT!*** 
Message: Could not move files
<class 'Exception'>
NoneType: None
----------------
2025-01-07_17:37:36  --->
Error level: ***ALERT!*** 
Message: Could not move files
<class 'Exception'>
NoneType: None
----------------
2025-01-07_17:37:49  --->
Error level: --Message-- 
Message: Zipfile contents for 2018
['accident.csv', 'cevent.csv', 'damage.csv', 'distract.csv', 'drimpair.csv', 'factor.csv', 'maneuver.csv', 'nmcrash.csv', 'nmimpair.csv', 'nmprior.csv', 'parkwork.csv', 'pbtype.csv', 'person.csv', 'safetyeq.csv', 'vehicle.csv', 'vevent.csv', 'violatn.csv', 'vision.csv', 'vpicdecode.csv', 'vpictrailerdecode.csv', 'vsoe.csv']
NoneType: None
----------------
2025-01-07_17:37:49  --->
Error level: --Message-- 
Message: Raw cols accident.csv: 
['CASENUM', 'REGION', 'PSU', 'PJ', 'PSU_VAR', 'URBANICITY', 'STRATUM', 'VE_TOTAL', 'VE_FORMS', 'PVH_INVL', 'PEDS', 'PERMVIT', 'PERNOTMVIT', 'NUM_INJ', 'MONTH', 'YEAR', 'DAY_WEEK', 'HOUR', 'MINUTE', 'HARM_EV', 'ALCOHOL', 'MAX_SEV', 'MAN_COLL', 'RELJCT1', 'RELJCT2', 'TYP_INT', 'WRK_ZONE', 'REL_ROAD', 'LGT_COND', 'WEATHER1', 'WEATHER2', 'WEATHER', 'SCH_BUS', 'INT_HWY', 'CF1', 'CF2', 'CF3', 'WKDY_IM', 'HOUR_IM', 'MINUTE_IM', 'EVENT1_IM', 'MANCOL_IM', 'RELJCT1_IM', 'RELJCT2_IM', 'LGTCON_IM', 'WEATHR_IM', 'MAXSEV_IM', 'NO_INJ_IM', 'ALCHL_IM', 'PSUSTRAT', 'WEIGHT']
NoneType: None
----------------
2025-01-07_17:37:49  --->
Error level: --Message-- 
Message: Normalized cols accident.csv: 
['casenum', 'region', 'psu', 'pj', 'psu_var', 'urbanicity', 'stratum', 've_total', 've_forms', 'pvh_invl', 'peds', 'permvit', 'pernotmvit', 'num_inj', 'month', 'year', 'day_week', 'hour', 'minute', 'harm_ev', 'alcohol', 'max_sev', 'man_coll', 'reljct1', 'reljct2', 'typ_int', 'wrk_zone', 'rel_road', 'lgt_cond', 'weather1', 'weather2', 'weather', 'sch_bus', 'int_hwy', 'cf1', 'cf2', 'cf3', 'wkdy_im', 'hour_im', 'minute_im', 'event1_im', 'mancol_im', 'reljct1_im', 'reljct2_im', 'lgtcon_im', 'weathr_im', 'maxsev_im', 'no_inj_im', 'alchl_im', 'psustrat', 'weight']
NoneType: None
----------------
2025-01-07_17:37:50  --->
Error level: --Message-- 
Message: Renamed cols accident.csv: 
['case_num', 'region', 'psu', 'pj', 'psu_var', 'urbancity', 'stratum', 'vehicles', 'moving', 'not_moving', 'pedestrian', 'occupants', 'notin_veh', 'num_inj', 'month', 'year', 'day_week', 'hour', 'minute', 'harm_ev', 'alcohol', 'max_sev', 'collision', 'reljct1', 'reljct2', 'intersection', 'workzone', 'roadway', 'lgt_cond', 'weather', 'weather2', 'weather', 'sch_bus', 'highway', 'cf1', 'cf2', 'cf3', 'wkdy_im', 'hour_im', 'minute_im', 'event1_im', 'mancol_im', 'reljct1_im', 'related_junct', 'lighting', 'weathr_im', 'max_injury', 'injuries', 'alchl_im', 'psustrat', 'weight']
NoneType: None
----------------
2025-01-07_17:37:50  --->
Error level: --Message-- 
Message: Duplicate columns detected
['weather']
NoneType: None
----------------
2025-01-07_17:38:38  --->
Error level: ***ALERT!*** 
Message: Could not move files
<class 'Exception'>
NoneType: None
----------------
2025-01-07_17:38:38  --->
Error level: ***ALERT!*** 
Message: Could not move files
<class 'Exception'>
NoneType: None
----------------
2025-01-07_17:38:38  --->
Error level: ***ALERT!*** 
Message: Could not move files
<class 'Exception'>
NoneType: None
----------------
2025-01-07_17:39:01  --->
Error level: --Message-- 
Message: Zipfile contents for 2019
['accident.csv', 'cevents.csv', 'damage.csv', 'distract.csv', 'drimpair.csv', 'factor.csv', 'maneuver.csv', 'nmcrash.csv', 'nmdistract.csv', 'nmimpair.csv', 'nmprior.csv', 'parkwork.csv', 'pbtype.csv', 'person.csv', 'safetyeq.csv', 'vehicle.csv', 'vevent.csv', 'violatn.csv', 'vision.csv', 'vpicdecode.csv', 'vpictrailerdecode.csv', 'vsoe.csv']
NoneType: None
----------------
2025-01-07_17:39:04  --->
Error level: --Message-- 
Message: Raw cols accident.csv: 
['CASENUM', 'STRATUM', 'STRATUMNAME', 'REGION', 'REGIONNAME', 'PSU', 'PJ', 'PSU_VAR', 'URBANICITY', 'URBANICITYNAME', 'VE_TOTAL', 'VE_FORMS', 'PVH_INVL', 'PEDS', 'PERMVIT', 'PERNOTMVIT', 'NUM_INJ', 'NUM_INJNAME', 'MONTH', 'MONTHNAME', 'YEAR', 'YEARNAME', 'DAY_WEEK', 'DAY_WEEKNAME', 'HOUR', 'HOURNAME', 'MINUTE', 'MINUTENAME', 'HARM_EV', 'HARM_EVNAME', 'ALCOHOL', 'ALCOHOLNAME', 'MAX_SEV', 'MAX_SEVNAME', 'MAN_COLL', 'MAN_COLLNAME', 'RELJCT1', 'RELJCT1NAME', 'RELJCT2', 'RELJCT2NAME', 'TYP_INT', 'TYP_INTNAME', 'WRK_ZONE', 'WRK_ZONENAME', 'REL_ROAD', 'REL_ROADNAME', 'LGT_COND', 'LGT_CONDNAME', 'WEATHER1', 'WEATHER1NAME', 'WEATHER2', 'WEATHER2NAME', 'WEATHER', 'WEATHERNAME', 'SCH_BUS', 'SCH_BUSNAME', 'INT_HWY', 'INT_HWYNAME', 'CF1', 'CF1NAME', 'CF2', 'CF2NAME', 'CF3', 'CF3NAME', 'PSUSTRAT', 'WEIGHT', 'WKDY_IM', 'WKDY_IMNAME', 'HOUR_IM', 'HOUR_IMNAME', 'MINUTE_IM', 'MINUTE_IMNAME', 'EVENT1_IM', 'EVENT1_IMNAME', 'MANCOL_IM', 'MANCOL_IMNAME', 'RELJCT2_IM', 'RELJCT2_IMNAME', 'LGTCON_IM', 'LGTCON_IMNAME', 'WEATHR_IM', 'WEATHR_IMNAME', 'MAXSEV_IM', 'MAXSEV_IMNAME', 'NO_INJ_IM', 'NO_INJ_IMNAME', 'ALCHL_IM', 'ALCHL_IMNAME']
NoneType: None
----------------
2025-01-07_17:39:04  --->
Error level: --Message-- 
Message: Normalized cols accident.csv: 
['casenum', 'stratum', 'stratumname', 'region', 'regionname', 'psu', 'pj', 'psu_var', 'urbanicity', 'urbanicityname', 've_total', 've_forms', 'pvh_invl', 'peds', 'permvit', 'pernotmvit', 'num_inj', 'num_injname', 'month', 'monthname', 'year', 'yearname', 'day_week', 'day_weekname', 'hour', 'hourname', 'minute', 'minutename', 'harm_ev', 'harm_evname', 'alcohol', 'alcoholname', 'max_sev', 'max_sevname', 'man_coll', 'man_collname', 'reljct1', 'reljct1name', 'reljct2', 'reljct2name', 'typ_int', 'typ_intname', 'wrk_zone', 'wrk_zonename', 'rel_road', 'rel_roadname', 'lgt_cond', 'lgt_condname', 'weather1', 'weather1name', 'weather2', 'weather2name', 'weather', 'weathername', 'sch_bus', 'sch_busname', 'int_hwy', 'int_hwyname', 'cf1', 'cf1name', 'cf2', 'cf2name', 'cf3', 'cf3name', 'psustrat', 'weight', 'wkdy_im', 'wkdy_imname', 'hour_im', 'hour_imname', 'minute_im', 'minute_imname', 'event1_im', 'event1_imname', 'mancol_im', 'mancol_imname', 'reljct2_im', 'reljct2_imname', 'lgtcon_im', 'lgtcon_imname', 'weathr_im', 'weathr_imname', 'maxsev_im', 'maxsev_imname', 'no_inj_im', 'no_inj_imname', 'alchl_im', 'alchl_imname']
NoneType: None
----------------
2025-01-07_17:39:04  --->
Error level: --Message-- 
Message: Renamed cols accident.csv: 
['case_num', 'stratum', 'stratumname', 'region', 'regionname', 'psu', 'pj', 'psu_var', 'urbancity', 'urbanicityname', 'vehicles', 'moving', 'not_moving', 'pedestrian', 'occupants', 'notin_veh', 'num_inj', 'num_injname', 'month', 'monthname', 'year', 'yearname', 'day_week', 'day_weekname', 'hour', 'hourname', 'minute', 'minutename', 'harm_ev', 'harm_evname', 'alcohol', 'alcoholname', 'max_sev', 'max_sevname', 'collision', 'man_collname', 'reljct1', 'reljct1name', 'reljct2', 'reljct2name', 'intersection', 'typ_intname', 'workzone', 'wrk_zonename', 'roadway', 'rel_roadname', 'lgt_cond', 'lgt_condname', 'weather', 'weather1name', 'weather2', 'weather2name', 'weather', 'weathername', 'sch_bus', 'sch_busname', 'highway', 'int_hwyname', 'cf1', 'cf1name', 'cf2', 'cf2name', 'cf3', 'cf3name', 'psustrat', 'weight', 'wkdy_im', 'wkdy_imname', 'hour_im', 'hour_imname', 'minute_im', 'minute_imname', 'event1_im', 'event1_imname', 'mancol_im', 'mancol_imname', 'related_junct', 'reljct2_imname', 'lighting', 'lgtcon_imname', 'weathr_im', 'weathr_imname', 'max_injury', 'maxsev_imname', 'injuries', 'no_inj_imname', 'alchl_im', 'alchl_imname']
NoneType: None
----------------
2025-01-07_17:39:04  --->
Error level: --Message-- 
Message: Duplicate columns detected
['weather']
NoneType: None
----------------
2025-01-07_17:39:07  --->
Error level: *Warning* 
Message: loading in utf-8 failed for C:/Users/cojac/Projects/crss/data/sourcedata/VEHICLE.CSV.
<class 'UnicodeDecodeError'>
Traceback (most recent call last):
  File "parsers.pyx", line 1120, in pandas._libs.parsers.TextReader._convert_tokens
  File "parsers.pyx", line 1272, in pandas._libs.parsers.TextReader._convert_with_dtype
  File "parsers.pyx", line 1285, in pandas._libs.parsers.TextReader._string_convert
  File "parsers.pyx", line 1535, in pandas._libs.parsers._string_box_utf8
UnicodeDecodeError: 'utf-8' codec can't decode byte 0xe9 in position 19: invalid continuation byte

During handling of the above exception, another exception occurred:

Traceback (most recent call last):
  File "c:\Users\cojac\Projects\crss\src\crsstransform.py", line 21, in detect_encoding
    return pd.read_csv(file_path, encoding="utf-8", low_memory=False)
  File "C:\Users\cojac\AppData\Local\Packages\PythonSoftwareFoundation.Python.3.10_qbz5n2kfra8p0\LocalCache\local-packages\Python310\site-packages\pandas\io\parsers\readers.py", line 1026, in read_csv
    return _read(filepath_or_buffer, kwds)
  File "C:\Users\cojac\AppData\Local\Packages\PythonSoftwareFoundation.Python.3.10_qbz5n2kfra8p0\LocalCache\local-packages\Python310\site-packages\pandas\io\parsers\readers.py", line 626, in _read
    return parser.read(nrows)
  File "C:\Users\cojac\AppData\Local\Packages\PythonSoftwareFoundation.Python.3.10_qbz5n2kfra8p0\LocalCache\local-packages\Python310\site-packages\pandas\io\parsers\readers.py", line 1923, in read
    ) = self._engine.read(  # type: ignore[attr-defined]
  File "C:\Users\cojac\AppData\Local\Packages\PythonSoftwareFoundation.Python.3.10_qbz5n2kfra8p0\LocalCache\local-packages\Python310\site-packages\pandas\io\parsers\c_parser_wrapper.py", line 239, in read
    data = self._reader.read(nrows)
  File "parsers.pyx", line 820, in pandas._libs.parsers.TextReader.read
  File "parsers.pyx", line 921, in pandas._libs.parsers.TextReader._read_rows
  File "parsers.pyx", line 1066, in pandas._libs.parsers.TextReader._convert_column_data
  File "parsers.pyx", line 1127, in pandas._libs.parsers.TextReader._convert_tokens
  File "parsers.pyx", line 1272, in pandas._libs.parsers.TextReader._convert_with_dtype
  File "parsers.pyx", line 1285, in pandas._libs.parsers.TextReader._string_convert
  File "parsers.pyx", line 1535, in pandas._libs.parsers._string_box_utf8
UnicodeDecodeError: 'utf-8' codec can't decode byte 0xe9 in position 19: invalid continuation byte
----------------
2025-01-07_17:39:07  --->
Error level: *Warning* 
Message: Encoding fallback to ISO-8859-1 failed for C:/Users/cojac/Projects/crss/data/sourcedata/VEHICLE.CSV, trying other encodings.
<class 'Exception'>
Traceback (most recent call last):
  File "parsers.pyx", line 1120, in pandas._libs.parsers.TextReader._convert_tokens
  File "parsers.pyx", line 1272, in pandas._libs.parsers.TextReader._convert_with_dtype
  File "parsers.pyx", line 1285, in pandas._libs.parsers.TextReader._string_convert
  File "parsers.pyx", line 1535, in pandas._libs.parsers._string_box_utf8
UnicodeDecodeError: 'utf-8' codec can't decode byte 0xe9 in position 19: invalid continuation byte

During handling of the above exception, another exception occurred:

Traceback (most recent call last):
  File "c:\Users\cojac\Projects\crss\src\crsstransform.py", line 21, in detect_encoding
    return pd.read_csv(file_path, encoding="utf-8", low_memory=False)
  File "C:\Users\cojac\AppData\Local\Packages\PythonSoftwareFoundation.Python.3.10_qbz5n2kfra8p0\LocalCache\local-packages\Python310\site-packages\pandas\io\parsers\readers.py", line 1026, in read_csv
    return _read(filepath_or_buffer, kwds)
  File "C:\Users\cojac\AppData\Local\Packages\PythonSoftwareFoundation.Python.3.10_qbz5n2kfra8p0\LocalCache\local-packages\Python310\site-packages\pandas\io\parsers\readers.py", line 626, in _read
    return parser.read(nrows)
  File "C:\Users\cojac\AppData\Local\Packages\PythonSoftwareFoundation.Python.3.10_qbz5n2kfra8p0\LocalCache\local-packages\Python310\site-packages\pandas\io\parsers\readers.py", line 1923, in read
    ) = self._engine.read(  # type: ignore[attr-defined]
  File "C:\Users\cojac\AppData\Local\Packages\PythonSoftwareFoundation.Python.3.10_qbz5n2kfra8p0\LocalCache\local-packages\Python310\site-packages\pandas\io\parsers\c_parser_wrapper.py", line 239, in read
    data = self._reader.read(nrows)
  File "parsers.pyx", line 820, in pandas._libs.parsers.TextReader.read
  File "parsers.pyx", line 921, in pandas._libs.parsers.TextReader._read_rows
  File "parsers.pyx", line 1066, in pandas._libs.parsers.TextReader._convert_column_data
  File "parsers.pyx", line 1127, in pandas._libs.parsers.TextReader._convert_tokens
  File "parsers.pyx", line 1272, in pandas._libs.parsers.TextReader._convert_with_dtype
  File "parsers.pyx", line 1285, in pandas._libs.parsers.TextReader._string_convert
  File "parsers.pyx", line 1535, in pandas._libs.parsers._string_box_utf8
UnicodeDecodeError: 'utf-8' codec can't decode byte 0xe9 in position 19: invalid continuation byte

During handling of the above exception, another exception occurred:

Traceback (most recent call last):
  File "c:\Users\cojac\Projects\crss\src\crsstransform.py", line 31, in detect_encoding
    return pd.read_csv(file_path, encoding=detected_encoding, low_memory=False)
  File "C:\Users\cojac\AppData\Local\Packages\PythonSoftwareFoundation.Python.3.10_qbz5n2kfra8p0\LocalCache\local-packages\Python310\site-packages\pandas\io\parsers\readers.py", line 1026, in read_csv
    return _read(filepath_or_buffer, kwds)
  File "C:\Users\cojac\AppData\Local\Packages\PythonSoftwareFoundation.Python.3.10_qbz5n2kfra8p0\LocalCache\local-packages\Python310\site-packages\pandas\io\parsers\readers.py", line 626, in _read
    return parser.read(nrows)
  File "C:\Users\cojac\AppData\Local\Packages\PythonSoftwareFoundation.Python.3.10_qbz5n2kfra8p0\LocalCache\local-packages\Python310\site-packages\pandas\io\parsers\readers.py", line 1923, in read
    ) = self._engine.read(  # type: ignore[attr-defined]
  File "C:\Users\cojac\AppData\Local\Packages\PythonSoftwareFoundation.Python.3.10_qbz5n2kfra8p0\LocalCache\local-packages\Python310\site-packages\pandas\io\parsers\c_parser_wrapper.py", line 239, in read
    data = self._reader.read(nrows)
  File "parsers.pyx", line 820, in pandas._libs.parsers.TextReader.read
  File "parsers.pyx", line 914, in pandas._libs.parsers.TextReader._read_rows
  File "parsers.pyx", line 891, in pandas._libs.parsers.TextReader._check_tokenize_status
  File "parsers.pyx", line 2053, in pandas._libs.parsers.raise_parser_error
UnicodeDecodeError: 'ascii' codec can't decode byte 0x96 in position 252743: ordinal not in range(128)
----------------
2025-01-07_17:39:15  --->
Error level: *Warning* 
Message: loading in utf-8 failed for C:/Users/cojac/Projects/crss/data/sourcedata/PARKWORK.CSV.
<class 'UnicodeDecodeError'>
Traceback (most recent call last):
  File "parsers.pyx", line 1120, in pandas._libs.parsers.TextReader._convert_tokens
  File "parsers.pyx", line 1272, in pandas._libs.parsers.TextReader._convert_with_dtype
  File "parsers.pyx", line 1285, in pandas._libs.parsers.TextReader._string_convert
  File "parsers.pyx", line 1535, in pandas._libs.parsers._string_box_utf8
UnicodeDecodeError: 'utf-8' codec can't decode byte 0xe9 in position 19: invalid continuation byte

During handling of the above exception, another exception occurred:

Traceback (most recent call last):
  File "c:\Users\cojac\Projects\crss\src\crsstransform.py", line 21, in detect_encoding
    return pd.read_csv(file_path, encoding="utf-8", low_memory=False)
  File "C:\Users\cojac\AppData\Local\Packages\PythonSoftwareFoundation.Python.3.10_qbz5n2kfra8p0\LocalCache\local-packages\Python310\site-packages\pandas\io\parsers\readers.py", line 1026, in read_csv
    return _read(filepath_or_buffer, kwds)
  File "C:\Users\cojac\AppData\Local\Packages\PythonSoftwareFoundation.Python.3.10_qbz5n2kfra8p0\LocalCache\local-packages\Python310\site-packages\pandas\io\parsers\readers.py", line 626, in _read
    return parser.read(nrows)
  File "C:\Users\cojac\AppData\Local\Packages\PythonSoftwareFoundation.Python.3.10_qbz5n2kfra8p0\LocalCache\local-packages\Python310\site-packages\pandas\io\parsers\readers.py", line 1923, in read
    ) = self._engine.read(  # type: ignore[attr-defined]
  File "C:\Users\cojac\AppData\Local\Packages\PythonSoftwareFoundation.Python.3.10_qbz5n2kfra8p0\LocalCache\local-packages\Python310\site-packages\pandas\io\parsers\c_parser_wrapper.py", line 239, in read
    data = self._reader.read(nrows)
  File "parsers.pyx", line 820, in pandas._libs.parsers.TextReader.read
  File "parsers.pyx", line 921, in pandas._libs.parsers.TextReader._read_rows
  File "parsers.pyx", line 1066, in pandas._libs.parsers.TextReader._convert_column_data
  File "parsers.pyx", line 1127, in pandas._libs.parsers.TextReader._convert_tokens
  File "parsers.pyx", line 1272, in pandas._libs.parsers.TextReader._convert_with_dtype
  File "parsers.pyx", line 1285, in pandas._libs.parsers.TextReader._string_convert
  File "parsers.pyx", line 1535, in pandas._libs.parsers._string_box_utf8
UnicodeDecodeError: 'utf-8' codec can't decode byte 0xe9 in position 19: invalid continuation byte
----------------
2025-01-07_17:39:15  --->
Error level: *Warning* 
Message: Encoding fallback to ISO-8859-1 failed for C:/Users/cojac/Projects/crss/data/sourcedata/PARKWORK.CSV, trying other encodings.
<class 'Exception'>
Traceback (most recent call last):
  File "parsers.pyx", line 1120, in pandas._libs.parsers.TextReader._convert_tokens
  File "parsers.pyx", line 1272, in pandas._libs.parsers.TextReader._convert_with_dtype
  File "parsers.pyx", line 1285, in pandas._libs.parsers.TextReader._string_convert
  File "parsers.pyx", line 1535, in pandas._libs.parsers._string_box_utf8
UnicodeDecodeError: 'utf-8' codec can't decode byte 0xe9 in position 19: invalid continuation byte

During handling of the above exception, another exception occurred:

Traceback (most recent call last):
  File "c:\Users\cojac\Projects\crss\src\crsstransform.py", line 21, in detect_encoding
    return pd.read_csv(file_path, encoding="utf-8", low_memory=False)
  File "C:\Users\cojac\AppData\Local\Packages\PythonSoftwareFoundation.Python.3.10_qbz5n2kfra8p0\LocalCache\local-packages\Python310\site-packages\pandas\io\parsers\readers.py", line 1026, in read_csv
    return _read(filepath_or_buffer, kwds)
  File "C:\Users\cojac\AppData\Local\Packages\PythonSoftwareFoundation.Python.3.10_qbz5n2kfra8p0\LocalCache\local-packages\Python310\site-packages\pandas\io\parsers\readers.py", line 626, in _read
    return parser.read(nrows)
  File "C:\Users\cojac\AppData\Local\Packages\PythonSoftwareFoundation.Python.3.10_qbz5n2kfra8p0\LocalCache\local-packages\Python310\site-packages\pandas\io\parsers\readers.py", line 1923, in read
    ) = self._engine.read(  # type: ignore[attr-defined]
  File "C:\Users\cojac\AppData\Local\Packages\PythonSoftwareFoundation.Python.3.10_qbz5n2kfra8p0\LocalCache\local-packages\Python310\site-packages\pandas\io\parsers\c_parser_wrapper.py", line 239, in read
    data = self._reader.read(nrows)
  File "parsers.pyx", line 820, in pandas._libs.parsers.TextReader.read
  File "parsers.pyx", line 921, in pandas._libs.parsers.TextReader._read_rows
  File "parsers.pyx", line 1066, in pandas._libs.parsers.TextReader._convert_column_data
  File "parsers.pyx", line 1127, in pandas._libs.parsers.TextReader._convert_tokens
  File "parsers.pyx", line 1272, in pandas._libs.parsers.TextReader._convert_with_dtype
  File "parsers.pyx", line 1285, in pandas._libs.parsers.TextReader._string_convert
  File "parsers.pyx", line 1535, in pandas._libs.parsers._string_box_utf8
UnicodeDecodeError: 'utf-8' codec can't decode byte 0xe9 in position 19: invalid continuation byte

During handling of the above exception, another exception occurred:

Traceback (most recent call last):
  File "c:\Users\cojac\Projects\crss\src\crsstransform.py", line 31, in detect_encoding
    return pd.read_csv(file_path, encoding=detected_encoding, low_memory=False)
  File "C:\Users\cojac\AppData\Local\Packages\PythonSoftwareFoundation.Python.3.10_qbz5n2kfra8p0\LocalCache\local-packages\Python310\site-packages\pandas\io\parsers\readers.py", line 1026, in read_csv
    return _read(filepath_or_buffer, kwds)
  File "C:\Users\cojac\AppData\Local\Packages\PythonSoftwareFoundation.Python.3.10_qbz5n2kfra8p0\LocalCache\local-packages\Python310\site-packages\pandas\io\parsers\readers.py", line 620, in _read
    parser = TextFileReader(filepath_or_buffer, **kwds)
  File "C:\Users\cojac\AppData\Local\Packages\PythonSoftwareFoundation.Python.3.10_qbz5n2kfra8p0\LocalCache\local-packages\Python310\site-packages\pandas\io\parsers\readers.py", line 1620, in __init__
    self._engine = self._make_engine(f, self.engine)
  File "C:\Users\cojac\AppData\Local\Packages\PythonSoftwareFoundation.Python.3.10_qbz5n2kfra8p0\LocalCache\local-packages\Python310\site-packages\pandas\io\parsers\readers.py", line 1898, in _make_engine
    return mapping[engine](f, **self.options)
  File "C:\Users\cojac\AppData\Local\Packages\PythonSoftwareFoundation.Python.3.10_qbz5n2kfra8p0\LocalCache\local-packages\Python310\site-packages\pandas\io\parsers\c_parser_wrapper.py", line 93, in __init__
    self._reader = parsers.TextReader(src, **kwds)
  File "parsers.pyx", line 574, in pandas._libs.parsers.TextReader.__cinit__
  File "parsers.pyx", line 663, in pandas._libs.parsers.TextReader._get_header
  File "parsers.pyx", line 874, in pandas._libs.parsers.TextReader._tokenize_rows
  File "parsers.pyx", line 891, in pandas._libs.parsers.TextReader._check_tokenize_status
  File "parsers.pyx", line 2053, in pandas._libs.parsers.raise_parser_error
UnicodeDecodeError: 'ascii' codec can't decode byte 0x96 in position 129673: ordinal not in range(128)
----------------
2025-01-07_17:39:18  --->
Error level: *Warning* 
Message: loading in utf-8 failed for C:/Users/cojac/Projects/crss/data/sourcedata/PERSON.CSV.
<class 'UnicodeDecodeError'>
Traceback (most recent call last):
  File "parsers.pyx", line 1120, in pandas._libs.parsers.TextReader._convert_tokens
  File "parsers.pyx", line 1272, in pandas._libs.parsers.TextReader._convert_with_dtype
  File "parsers.pyx", line 1285, in pandas._libs.parsers.TextReader._string_convert
  File "parsers.pyx", line 1535, in pandas._libs.parsers._string_box_utf8
UnicodeDecodeError: 'utf-8' codec can't decode byte 0xe9 in position 19: invalid continuation byte

During handling of the above exception, another exception occurred:

Traceback (most recent call last):
  File "c:\Users\cojac\Projects\crss\src\crsstransform.py", line 21, in detect_encoding
    return pd.read_csv(file_path, encoding="utf-8", low_memory=False)
  File "C:\Users\cojac\AppData\Local\Packages\PythonSoftwareFoundation.Python.3.10_qbz5n2kfra8p0\LocalCache\local-packages\Python310\site-packages\pandas\io\parsers\readers.py", line 1026, in read_csv
    return _read(filepath_or_buffer, kwds)
  File "C:\Users\cojac\AppData\Local\Packages\PythonSoftwareFoundation.Python.3.10_qbz5n2kfra8p0\LocalCache\local-packages\Python310\site-packages\pandas\io\parsers\readers.py", line 626, in _read
    return parser.read(nrows)
  File "C:\Users\cojac\AppData\Local\Packages\PythonSoftwareFoundation.Python.3.10_qbz5n2kfra8p0\LocalCache\local-packages\Python310\site-packages\pandas\io\parsers\readers.py", line 1923, in read
    ) = self._engine.read(  # type: ignore[attr-defined]
  File "C:\Users\cojac\AppData\Local\Packages\PythonSoftwareFoundation.Python.3.10_qbz5n2kfra8p0\LocalCache\local-packages\Python310\site-packages\pandas\io\parsers\c_parser_wrapper.py", line 239, in read
    data = self._reader.read(nrows)
  File "parsers.pyx", line 820, in pandas._libs.parsers.TextReader.read
  File "parsers.pyx", line 921, in pandas._libs.parsers.TextReader._read_rows
  File "parsers.pyx", line 1066, in pandas._libs.parsers.TextReader._convert_column_data
  File "parsers.pyx", line 1127, in pandas._libs.parsers.TextReader._convert_tokens
  File "parsers.pyx", line 1272, in pandas._libs.parsers.TextReader._convert_with_dtype
  File "parsers.pyx", line 1285, in pandas._libs.parsers.TextReader._string_convert
  File "parsers.pyx", line 1535, in pandas._libs.parsers._string_box_utf8
UnicodeDecodeError: 'utf-8' codec can't decode byte 0xe9 in position 19: invalid continuation byte
----------------
2025-01-07_17:39:18  --->
Error level: *Warning* 
Message: Encoding fallback to ISO-8859-1 failed for C:/Users/cojac/Projects/crss/data/sourcedata/PERSON.CSV, trying other encodings.
<class 'Exception'>
Traceback (most recent call last):
  File "parsers.pyx", line 1120, in pandas._libs.parsers.TextReader._convert_tokens
  File "parsers.pyx", line 1272, in pandas._libs.parsers.TextReader._convert_with_dtype
  File "parsers.pyx", line 1285, in pandas._libs.parsers.TextReader._string_convert
  File "parsers.pyx", line 1535, in pandas._libs.parsers._string_box_utf8
UnicodeDecodeError: 'utf-8' codec can't decode byte 0xe9 in position 19: invalid continuation byte

During handling of the above exception, another exception occurred:

Traceback (most recent call last):
  File "c:\Users\cojac\Projects\crss\src\crsstransform.py", line 21, in detect_encoding
    return pd.read_csv(file_path, encoding="utf-8", low_memory=False)
  File "C:\Users\cojac\AppData\Local\Packages\PythonSoftwareFoundation.Python.3.10_qbz5n2kfra8p0\LocalCache\local-packages\Python310\site-packages\pandas\io\parsers\readers.py", line 1026, in read_csv
    return _read(filepath_or_buffer, kwds)
  File "C:\Users\cojac\AppData\Local\Packages\PythonSoftwareFoundation.Python.3.10_qbz5n2kfra8p0\LocalCache\local-packages\Python310\site-packages\pandas\io\parsers\readers.py", line 626, in _read
    return parser.read(nrows)
  File "C:\Users\cojac\AppData\Local\Packages\PythonSoftwareFoundation.Python.3.10_qbz5n2kfra8p0\LocalCache\local-packages\Python310\site-packages\pandas\io\parsers\readers.py", line 1923, in read
    ) = self._engine.read(  # type: ignore[attr-defined]
  File "C:\Users\cojac\AppData\Local\Packages\PythonSoftwareFoundation.Python.3.10_qbz5n2kfra8p0\LocalCache\local-packages\Python310\site-packages\pandas\io\parsers\c_parser_wrapper.py", line 239, in read
    data = self._reader.read(nrows)
  File "parsers.pyx", line 820, in pandas._libs.parsers.TextReader.read
  File "parsers.pyx", line 921, in pandas._libs.parsers.TextReader._read_rows
  File "parsers.pyx", line 1066, in pandas._libs.parsers.TextReader._convert_column_data
  File "parsers.pyx", line 1127, in pandas._libs.parsers.TextReader._convert_tokens
  File "parsers.pyx", line 1272, in pandas._libs.parsers.TextReader._convert_with_dtype
  File "parsers.pyx", line 1285, in pandas._libs.parsers.TextReader._string_convert
  File "parsers.pyx", line 1535, in pandas._libs.parsers._string_box_utf8
UnicodeDecodeError: 'utf-8' codec can't decode byte 0xe9 in position 19: invalid continuation byte

During handling of the above exception, another exception occurred:

Traceback (most recent call last):
  File "c:\Users\cojac\Projects\crss\src\crsstransform.py", line 31, in detect_encoding
    return pd.read_csv(file_path, encoding=detected_encoding, low_memory=False)
  File "C:\Users\cojac\AppData\Local\Packages\PythonSoftwareFoundation.Python.3.10_qbz5n2kfra8p0\LocalCache\local-packages\Python310\site-packages\pandas\io\parsers\readers.py", line 1026, in read_csv
    return _read(filepath_or_buffer, kwds)
  File "C:\Users\cojac\AppData\Local\Packages\PythonSoftwareFoundation.Python.3.10_qbz5n2kfra8p0\LocalCache\local-packages\Python310\site-packages\pandas\io\parsers\readers.py", line 626, in _read
    return parser.read(nrows)
  File "C:\Users\cojac\AppData\Local\Packages\PythonSoftwareFoundation.Python.3.10_qbz5n2kfra8p0\LocalCache\local-packages\Python310\site-packages\pandas\io\parsers\readers.py", line 1923, in read
    ) = self._engine.read(  # type: ignore[attr-defined]
  File "C:\Users\cojac\AppData\Local\Packages\PythonSoftwareFoundation.Python.3.10_qbz5n2kfra8p0\LocalCache\local-packages\Python310\site-packages\pandas\io\parsers\c_parser_wrapper.py", line 239, in read
    data = self._reader.read(nrows)
  File "parsers.pyx", line 820, in pandas._libs.parsers.TextReader.read
  File "parsers.pyx", line 914, in pandas._libs.parsers.TextReader._read_rows
  File "parsers.pyx", line 891, in pandas._libs.parsers.TextReader._check_tokenize_status
  File "parsers.pyx", line 2053, in pandas._libs.parsers.raise_parser_error
UnicodeDecodeError: 'ascii' codec can't decode byte 0x96 in position 240860: ordinal not in range(128)
----------------
2025-01-07_17:40:25  --->
Error level: ***ALERT!*** 
Message: Could not move files
<class 'Exception'>
NoneType: None
----------------
2025-01-07_17:40:25  --->
Error level: ***ALERT!*** 
Message: Could not move files
<class 'Exception'>
NoneType: None
----------------
2025-01-07_17:40:25  --->
Error level: ***ALERT!*** 
Message: Could not move files
<class 'Exception'>
NoneType: None
----------------
2025-01-07_17:40:53  --->
Error level: --Message-- 
Message: Zipfile contents for 2020
['crss2020csv/accident.csv', 'crss2020csv/cevent.csv', 'crss2020csv/crashrf.csv', 'crss2020csv/damage.csv', 'crss2020csv/distract.csv', 'crss2020csv/drimpair.csv', 'crss2020csv/driverrf.csv', 'crss2020csv/factor.csv', 'crss2020csv/maneuver.csv', 'crss2020csv/nmcrash.csv', 'crss2020csv/nmdistract.csv', 'crss2020csv/nmimpair.csv', 'crss2020csv/nmprior.csv', 'crss2020csv/parkwork.csv', 'crss2020csv/pbtype.csv', 'crss2020csv/person.csv', 'crss2020csv/personrf.csv', 'crss2020csv/pvehiclesf.csv', 'crss2020csv/safetyeq.csv', 'crss2020csv/vehicle.csv', 'crss2020csv/vehiclesf.csv', 'crss2020csv/vevent.csv', 'crss2020csv/violatn.csv', 'crss2020csv/vision.csv', 'crss2020csv/vpicdecode.csv', 'crss2020csv/vpictrailerdecode.csv', 'crss2020csv/vsoe.csv', 'crss2020csv/weather.csv']
NoneType: None
----------------
2025-01-07_17:40:56  --->
Error level: --Message-- 
Message: Raw cols accident.csv: 
['CASENUM', 'STRATUM', 'STRATUMNAME', 'REGION', 'REGIONNAME', 'PSU', 'PJ', 'PSU_VAR', 'URBANICITY', 'URBANICITYNAME', 'VE_TOTAL', 'VE_FORMS', 'PVH_INVL', 'PEDS', 'PERMVIT', 'PERNOTMVIT', 'NUM_INJ', 'NUM_INJNAME', 'MONTH', 'MONTHNAME', 'YEAR', 'YEARNAME', 'DAY_WEEK', 'DAY_WEEKNAME', 'HOUR', 'HOURNAME', 'MINUTE', 'MINUTENAME', 'HARM_EV', 'HARM_EVNAME', 'ALCOHOL', 'ALCOHOLNAME', 'MAX_SEV', 'MAX_SEVNAME', 'MAN_COLL', 'MAN_COLLNAME', 'RELJCT1', 'RELJCT1NAME', 'RELJCT2', 'RELJCT2NAME', 'TYP_INT', 'TYP_INTNAME', 'WRK_ZONE', 'WRK_ZONENAME', 'REL_ROAD', 'REL_ROADNAME', 'LGT_COND', 'LGT_CONDNAME', 'SCH_BUS', 'SCH_BUSNAME', 'INT_HWY', 'INT_HWYNAME', 'WEATHER', 'WEATHERNAME', 'WKDY_IM', 'WKDY_IMNAME', 'HOUR_IM', 'HOUR_IMNAME', 'MINUTE_IM', 'MINUTE_IMNAME', 'EVENT1_IM', 'EVENT1_IMNAME', 'MANCOL_IM', 'MANCOL_IMNAME', 'RELJCT1_IM', 'RELJCT1_IMNAME', 'RELJCT2_IM', 'RELJCT2_IMNAME', 'LGTCON_IM', 'LGTCON_IMNAME', 'WEATHR_IM', 'WEATHR_IMNAME', 'MAXSEV_IM', 'MAXSEV_IMNAME', 'NO_INJ_IM', 'NO_INJ_IMNAME', 'ALCHL_IM', 'ALCHL_IMNAME', 'PSUSTRAT', 'WEIGHT']
NoneType: None
----------------
2025-01-07_17:40:56  --->
Error level: --Message-- 
Message: Normalized cols accident.csv: 
['casenum', 'stratum', 'stratumname', 'region', 'regionname', 'psu', 'pj', 'psu_var', 'urbanicity', 'urbanicityname', 've_total', 've_forms', 'pvh_invl', 'peds', 'permvit', 'pernotmvit', 'num_inj', 'num_injname', 'month', 'monthname', 'year', 'yearname', 'day_week', 'day_weekname', 'hour', 'hourname', 'minute', 'minutename', 'harm_ev', 'harm_evname', 'alcohol', 'alcoholname', 'max_sev', 'max_sevname', 'man_coll', 'man_collname', 'reljct1', 'reljct1name', 'reljct2', 'reljct2name', 'typ_int', 'typ_intname', 'wrk_zone', 'wrk_zonename', 'rel_road', 'rel_roadname', 'lgt_cond', 'lgt_condname', 'sch_bus', 'sch_busname', 'int_hwy', 'int_hwyname', 'weather', 'weathername', 'wkdy_im', 'wkdy_imname', 'hour_im', 'hour_imname', 'minute_im', 'minute_imname', 'event1_im', 'event1_imname', 'mancol_im', 'mancol_imname', 'reljct1_im', 'reljct1_imname', 'reljct2_im', 'reljct2_imname', 'lgtcon_im', 'lgtcon_imname', 'weathr_im', 'weathr_imname', 'maxsev_im', 'maxsev_imname', 'no_inj_im', 'no_inj_imname', 'alchl_im', 'alchl_imname', 'psustrat', 'weight']
NoneType: None
----------------
2025-01-07_17:40:56  --->
Error level: --Message-- 
Message: Renamed cols accident.csv: 
['case_num', 'stratum', 'stratumname', 'region', 'regionname', 'psu', 'pj', 'psu_var', 'urbancity', 'urbanicityname', 'vehicles', 'moving', 'not_moving', 'pedestrian', 'occupants', 'notin_veh', 'num_inj', 'num_injname', 'month', 'monthname', 'year', 'yearname', 'day_week', 'day_weekname', 'hour', 'hourname', 'minute', 'minutename', 'harm_ev', 'harm_evname', 'alcohol', 'alcoholname', 'max_sev', 'max_sevname', 'collision', 'man_collname', 'reljct1', 'reljct1name', 'reljct2', 'reljct2name', 'intersection', 'typ_intname', 'workzone', 'wrk_zonename', 'roadway', 'rel_roadname', 'lgt_cond', 'lgt_condname', 'sch_bus', 'sch_busname', 'highway', 'int_hwyname', 'weather', 'weathername', 'wkdy_im', 'wkdy_imname', 'hour_im', 'hour_imname', 'minute_im', 'minute_imname', 'event1_im', 'event1_imname', 'mancol_im', 'mancol_imname', 'reljct1_im', 'reljct1_imname', 'related_junct', 'reljct2_imname', 'lighting', 'lgtcon_imname', 'weathr_im', 'weathr_imname', 'max_injury', 'maxsev_imname', 'injuries', 'no_inj_imname', 'alchl_im', 'alchl_imname', 'psustrat', 'weight']
NoneType: None
----------------
2025-01-07_17:40:59  --->
Error level: *Warning* 
Message: loading in utf-8 failed for C:/Users/cojac/Projects/crss/data/sourcedata/CRSS2020CSV/VEHICLE.CSV.
<class 'UnicodeDecodeError'>
Traceback (most recent call last):
  File "parsers.pyx", line 1120, in pandas._libs.parsers.TextReader._convert_tokens
  File "parsers.pyx", line 1272, in pandas._libs.parsers.TextReader._convert_with_dtype
  File "parsers.pyx", line 1285, in pandas._libs.parsers.TextReader._string_convert
  File "parsers.pyx", line 1535, in pandas._libs.parsers._string_box_utf8
UnicodeDecodeError: 'utf-8' codec can't decode byte 0xe9 in position 19: invalid continuation byte

During handling of the above exception, another exception occurred:

Traceback (most recent call last):
  File "c:\Users\cojac\Projects\crss\src\crsstransform.py", line 21, in detect_encoding
    return pd.read_csv(file_path, encoding="utf-8", low_memory=False)
  File "C:\Users\cojac\AppData\Local\Packages\PythonSoftwareFoundation.Python.3.10_qbz5n2kfra8p0\LocalCache\local-packages\Python310\site-packages\pandas\io\parsers\readers.py", line 1026, in read_csv
    return _read(filepath_or_buffer, kwds)
  File "C:\Users\cojac\AppData\Local\Packages\PythonSoftwareFoundation.Python.3.10_qbz5n2kfra8p0\LocalCache\local-packages\Python310\site-packages\pandas\io\parsers\readers.py", line 626, in _read
    return parser.read(nrows)
  File "C:\Users\cojac\AppData\Local\Packages\PythonSoftwareFoundation.Python.3.10_qbz5n2kfra8p0\LocalCache\local-packages\Python310\site-packages\pandas\io\parsers\readers.py", line 1923, in read
    ) = self._engine.read(  # type: ignore[attr-defined]
  File "C:\Users\cojac\AppData\Local\Packages\PythonSoftwareFoundation.Python.3.10_qbz5n2kfra8p0\LocalCache\local-packages\Python310\site-packages\pandas\io\parsers\c_parser_wrapper.py", line 239, in read
    data = self._reader.read(nrows)
  File "parsers.pyx", line 820, in pandas._libs.parsers.TextReader.read
  File "parsers.pyx", line 921, in pandas._libs.parsers.TextReader._read_rows
  File "parsers.pyx", line 1066, in pandas._libs.parsers.TextReader._convert_column_data
  File "parsers.pyx", line 1127, in pandas._libs.parsers.TextReader._convert_tokens
  File "parsers.pyx", line 1272, in pandas._libs.parsers.TextReader._convert_with_dtype
  File "parsers.pyx", line 1285, in pandas._libs.parsers.TextReader._string_convert
  File "parsers.pyx", line 1535, in pandas._libs.parsers._string_box_utf8
UnicodeDecodeError: 'utf-8' codec can't decode byte 0xe9 in position 19: invalid continuation byte
----------------
2025-01-07_17:40:59  --->
Error level: *Warning* 
Message: Encoding fallback to ISO-8859-1 failed for C:/Users/cojac/Projects/crss/data/sourcedata/CRSS2020CSV/VEHICLE.CSV, trying other encodings.
<class 'Exception'>
Traceback (most recent call last):
  File "parsers.pyx", line 1120, in pandas._libs.parsers.TextReader._convert_tokens
  File "parsers.pyx", line 1272, in pandas._libs.parsers.TextReader._convert_with_dtype
  File "parsers.pyx", line 1285, in pandas._libs.parsers.TextReader._string_convert
  File "parsers.pyx", line 1535, in pandas._libs.parsers._string_box_utf8
UnicodeDecodeError: 'utf-8' codec can't decode byte 0xe9 in position 19: invalid continuation byte

During handling of the above exception, another exception occurred:

Traceback (most recent call last):
  File "c:\Users\cojac\Projects\crss\src\crsstransform.py", line 21, in detect_encoding
    return pd.read_csv(file_path, encoding="utf-8", low_memory=False)
  File "C:\Users\cojac\AppData\Local\Packages\PythonSoftwareFoundation.Python.3.10_qbz5n2kfra8p0\LocalCache\local-packages\Python310\site-packages\pandas\io\parsers\readers.py", line 1026, in read_csv
    return _read(filepath_or_buffer, kwds)
  File "C:\Users\cojac\AppData\Local\Packages\PythonSoftwareFoundation.Python.3.10_qbz5n2kfra8p0\LocalCache\local-packages\Python310\site-packages\pandas\io\parsers\readers.py", line 626, in _read
    return parser.read(nrows)
  File "C:\Users\cojac\AppData\Local\Packages\PythonSoftwareFoundation.Python.3.10_qbz5n2kfra8p0\LocalCache\local-packages\Python310\site-packages\pandas\io\parsers\readers.py", line 1923, in read
    ) = self._engine.read(  # type: ignore[attr-defined]
  File "C:\Users\cojac\AppData\Local\Packages\PythonSoftwareFoundation.Python.3.10_qbz5n2kfra8p0\LocalCache\local-packages\Python310\site-packages\pandas\io\parsers\c_parser_wrapper.py", line 239, in read
    data = self._reader.read(nrows)
  File "parsers.pyx", line 820, in pandas._libs.parsers.TextReader.read
  File "parsers.pyx", line 921, in pandas._libs.parsers.TextReader._read_rows
  File "parsers.pyx", line 1066, in pandas._libs.parsers.TextReader._convert_column_data
  File "parsers.pyx", line 1127, in pandas._libs.parsers.TextReader._convert_tokens
  File "parsers.pyx", line 1272, in pandas._libs.parsers.TextReader._convert_with_dtype
  File "parsers.pyx", line 1285, in pandas._libs.parsers.TextReader._string_convert
  File "parsers.pyx", line 1535, in pandas._libs.parsers._string_box_utf8
UnicodeDecodeError: 'utf-8' codec can't decode byte 0xe9 in position 19: invalid continuation byte

During handling of the above exception, another exception occurred:

Traceback (most recent call last):
  File "c:\Users\cojac\Projects\crss\src\crsstransform.py", line 31, in detect_encoding
    return pd.read_csv(file_path, encoding=detected_encoding, low_memory=False)
  File "C:\Users\cojac\AppData\Local\Packages\PythonSoftwareFoundation.Python.3.10_qbz5n2kfra8p0\LocalCache\local-packages\Python310\site-packages\pandas\io\parsers\readers.py", line 1026, in read_csv
    return _read(filepath_or_buffer, kwds)
  File "C:\Users\cojac\AppData\Local\Packages\PythonSoftwareFoundation.Python.3.10_qbz5n2kfra8p0\LocalCache\local-packages\Python310\site-packages\pandas\io\parsers\readers.py", line 626, in _read
    return parser.read(nrows)
  File "C:\Users\cojac\AppData\Local\Packages\PythonSoftwareFoundation.Python.3.10_qbz5n2kfra8p0\LocalCache\local-packages\Python310\site-packages\pandas\io\parsers\readers.py", line 1923, in read
    ) = self._engine.read(  # type: ignore[attr-defined]
  File "C:\Users\cojac\AppData\Local\Packages\PythonSoftwareFoundation.Python.3.10_qbz5n2kfra8p0\LocalCache\local-packages\Python310\site-packages\pandas\io\parsers\c_parser_wrapper.py", line 239, in read
    data = self._reader.read(nrows)
  File "parsers.pyx", line 820, in pandas._libs.parsers.TextReader.read
  File "parsers.pyx", line 914, in pandas._libs.parsers.TextReader._read_rows
  File "parsers.pyx", line 891, in pandas._libs.parsers.TextReader._check_tokenize_status
  File "parsers.pyx", line 2053, in pandas._libs.parsers.raise_parser_error
UnicodeDecodeError: 'ascii' codec can't decode byte 0x96 in position 144378: ordinal not in range(128)
----------------
2025-01-07_17:41:07  --->
Error level: *Warning* 
Message: loading in utf-8 failed for C:/Users/cojac/Projects/crss/data/sourcedata/CRSS2020CSV/PARKWORK.CSV.
<class 'UnicodeDecodeError'>
Traceback (most recent call last):
  File "parsers.pyx", line 1120, in pandas._libs.parsers.TextReader._convert_tokens
  File "parsers.pyx", line 1272, in pandas._libs.parsers.TextReader._convert_with_dtype
  File "parsers.pyx", line 1285, in pandas._libs.parsers.TextReader._string_convert
  File "parsers.pyx", line 1535, in pandas._libs.parsers._string_box_utf8
UnicodeDecodeError: 'utf-8' codec can't decode byte 0x96 in position 7: invalid start byte

During handling of the above exception, another exception occurred:

Traceback (most recent call last):
  File "c:\Users\cojac\Projects\crss\src\crsstransform.py", line 21, in detect_encoding
    return pd.read_csv(file_path, encoding="utf-8", low_memory=False)
  File "C:\Users\cojac\AppData\Local\Packages\PythonSoftwareFoundation.Python.3.10_qbz5n2kfra8p0\LocalCache\local-packages\Python310\site-packages\pandas\io\parsers\readers.py", line 1026, in read_csv
    return _read(filepath_or_buffer, kwds)
  File "C:\Users\cojac\AppData\Local\Packages\PythonSoftwareFoundation.Python.3.10_qbz5n2kfra8p0\LocalCache\local-packages\Python310\site-packages\pandas\io\parsers\readers.py", line 626, in _read
    return parser.read(nrows)
  File "C:\Users\cojac\AppData\Local\Packages\PythonSoftwareFoundation.Python.3.10_qbz5n2kfra8p0\LocalCache\local-packages\Python310\site-packages\pandas\io\parsers\readers.py", line 1923, in read
    ) = self._engine.read(  # type: ignore[attr-defined]
  File "C:\Users\cojac\AppData\Local\Packages\PythonSoftwareFoundation.Python.3.10_qbz5n2kfra8p0\LocalCache\local-packages\Python310\site-packages\pandas\io\parsers\c_parser_wrapper.py", line 239, in read
    data = self._reader.read(nrows)
  File "parsers.pyx", line 820, in pandas._libs.parsers.TextReader.read
  File "parsers.pyx", line 921, in pandas._libs.parsers.TextReader._read_rows
  File "parsers.pyx", line 1066, in pandas._libs.parsers.TextReader._convert_column_data
  File "parsers.pyx", line 1127, in pandas._libs.parsers.TextReader._convert_tokens
  File "parsers.pyx", line 1272, in pandas._libs.parsers.TextReader._convert_with_dtype
  File "parsers.pyx", line 1285, in pandas._libs.parsers.TextReader._string_convert
  File "parsers.pyx", line 1535, in pandas._libs.parsers._string_box_utf8
UnicodeDecodeError: 'utf-8' codec can't decode byte 0x96 in position 7: invalid start byte
----------------
2025-01-07_17:41:12  --->
Error level: *Warning* 
Message: loading in utf-8 failed for C:/Users/cojac/Projects/crss/data/sourcedata/CRSS2020CSV/PERSON.CSV.
<class 'UnicodeDecodeError'>
Traceback (most recent call last):
  File "parsers.pyx", line 1120, in pandas._libs.parsers.TextReader._convert_tokens
  File "parsers.pyx", line 1272, in pandas._libs.parsers.TextReader._convert_with_dtype
  File "parsers.pyx", line 1285, in pandas._libs.parsers.TextReader._string_convert
  File "parsers.pyx", line 1535, in pandas._libs.parsers._string_box_utf8
UnicodeDecodeError: 'utf-8' codec can't decode byte 0xe9 in position 19: invalid continuation byte

During handling of the above exception, another exception occurred:

Traceback (most recent call last):
  File "c:\Users\cojac\Projects\crss\src\crsstransform.py", line 21, in detect_encoding
    return pd.read_csv(file_path, encoding="utf-8", low_memory=False)
  File "C:\Users\cojac\AppData\Local\Packages\PythonSoftwareFoundation.Python.3.10_qbz5n2kfra8p0\LocalCache\local-packages\Python310\site-packages\pandas\io\parsers\readers.py", line 1026, in read_csv
    return _read(filepath_or_buffer, kwds)
  File "C:\Users\cojac\AppData\Local\Packages\PythonSoftwareFoundation.Python.3.10_qbz5n2kfra8p0\LocalCache\local-packages\Python310\site-packages\pandas\io\parsers\readers.py", line 626, in _read
    return parser.read(nrows)
  File "C:\Users\cojac\AppData\Local\Packages\PythonSoftwareFoundation.Python.3.10_qbz5n2kfra8p0\LocalCache\local-packages\Python310\site-packages\pandas\io\parsers\readers.py", line 1923, in read
    ) = self._engine.read(  # type: ignore[attr-defined]
  File "C:\Users\cojac\AppData\Local\Packages\PythonSoftwareFoundation.Python.3.10_qbz5n2kfra8p0\LocalCache\local-packages\Python310\site-packages\pandas\io\parsers\c_parser_wrapper.py", line 239, in read
    data = self._reader.read(nrows)
  File "parsers.pyx", line 820, in pandas._libs.parsers.TextReader.read
  File "parsers.pyx", line 921, in pandas._libs.parsers.TextReader._read_rows
  File "parsers.pyx", line 1066, in pandas._libs.parsers.TextReader._convert_column_data
  File "parsers.pyx", line 1127, in pandas._libs.parsers.TextReader._convert_tokens
  File "parsers.pyx", line 1272, in pandas._libs.parsers.TextReader._convert_with_dtype
  File "parsers.pyx", line 1285, in pandas._libs.parsers.TextReader._string_convert
  File "parsers.pyx", line 1535, in pandas._libs.parsers._string_box_utf8
UnicodeDecodeError: 'utf-8' codec can't decode byte 0xe9 in position 19: invalid continuation byte
----------------
2025-01-07_17:41:12  --->
Error level: *Warning* 
Message: Encoding fallback to ISO-8859-1 failed for C:/Users/cojac/Projects/crss/data/sourcedata/CRSS2020CSV/PERSON.CSV, trying other encodings.
<class 'Exception'>
Traceback (most recent call last):
  File "parsers.pyx", line 1120, in pandas._libs.parsers.TextReader._convert_tokens
  File "parsers.pyx", line 1272, in pandas._libs.parsers.TextReader._convert_with_dtype
  File "parsers.pyx", line 1285, in pandas._libs.parsers.TextReader._string_convert
  File "parsers.pyx", line 1535, in pandas._libs.parsers._string_box_utf8
UnicodeDecodeError: 'utf-8' codec can't decode byte 0xe9 in position 19: invalid continuation byte

During handling of the above exception, another exception occurred:

Traceback (most recent call last):
  File "c:\Users\cojac\Projects\crss\src\crsstransform.py", line 21, in detect_encoding
    return pd.read_csv(file_path, encoding="utf-8", low_memory=False)
  File "C:\Users\cojac\AppData\Local\Packages\PythonSoftwareFoundation.Python.3.10_qbz5n2kfra8p0\LocalCache\local-packages\Python310\site-packages\pandas\io\parsers\readers.py", line 1026, in read_csv
    return _read(filepath_or_buffer, kwds)
  File "C:\Users\cojac\AppData\Local\Packages\PythonSoftwareFoundation.Python.3.10_qbz5n2kfra8p0\LocalCache\local-packages\Python310\site-packages\pandas\io\parsers\readers.py", line 626, in _read
    return parser.read(nrows)
  File "C:\Users\cojac\AppData\Local\Packages\PythonSoftwareFoundation.Python.3.10_qbz5n2kfra8p0\LocalCache\local-packages\Python310\site-packages\pandas\io\parsers\readers.py", line 1923, in read
    ) = self._engine.read(  # type: ignore[attr-defined]
  File "C:\Users\cojac\AppData\Local\Packages\PythonSoftwareFoundation.Python.3.10_qbz5n2kfra8p0\LocalCache\local-packages\Python310\site-packages\pandas\io\parsers\c_parser_wrapper.py", line 239, in read
    data = self._reader.read(nrows)
  File "parsers.pyx", line 820, in pandas._libs.parsers.TextReader.read
  File "parsers.pyx", line 921, in pandas._libs.parsers.TextReader._read_rows
  File "parsers.pyx", line 1066, in pandas._libs.parsers.TextReader._convert_column_data
  File "parsers.pyx", line 1127, in pandas._libs.parsers.TextReader._convert_tokens
  File "parsers.pyx", line 1272, in pandas._libs.parsers.TextReader._convert_with_dtype
  File "parsers.pyx", line 1285, in pandas._libs.parsers.TextReader._string_convert
  File "parsers.pyx", line 1535, in pandas._libs.parsers._string_box_utf8
UnicodeDecodeError: 'utf-8' codec can't decode byte 0xe9 in position 19: invalid continuation byte

During handling of the above exception, another exception occurred:

Traceback (most recent call last):
  File "c:\Users\cojac\Projects\crss\src\crsstransform.py", line 31, in detect_encoding
    return pd.read_csv(file_path, encoding=detected_encoding, low_memory=False)
  File "C:\Users\cojac\AppData\Local\Packages\PythonSoftwareFoundation.Python.3.10_qbz5n2kfra8p0\LocalCache\local-packages\Python310\site-packages\pandas\io\parsers\readers.py", line 1026, in read_csv
    return _read(filepath_or_buffer, kwds)
  File "C:\Users\cojac\AppData\Local\Packages\PythonSoftwareFoundation.Python.3.10_qbz5n2kfra8p0\LocalCache\local-packages\Python310\site-packages\pandas\io\parsers\readers.py", line 626, in _read
    return parser.read(nrows)
  File "C:\Users\cojac\AppData\Local\Packages\PythonSoftwareFoundation.Python.3.10_qbz5n2kfra8p0\LocalCache\local-packages\Python310\site-packages\pandas\io\parsers\readers.py", line 1923, in read
    ) = self._engine.read(  # type: ignore[attr-defined]
  File "C:\Users\cojac\AppData\Local\Packages\PythonSoftwareFoundation.Python.3.10_qbz5n2kfra8p0\LocalCache\local-packages\Python310\site-packages\pandas\io\parsers\c_parser_wrapper.py", line 239, in read
    data = self._reader.read(nrows)
  File "parsers.pyx", line 820, in pandas._libs.parsers.TextReader.read
  File "parsers.pyx", line 914, in pandas._libs.parsers.TextReader._read_rows
  File "parsers.pyx", line 891, in pandas._libs.parsers.TextReader._check_tokenize_status
  File "parsers.pyx", line 2053, in pandas._libs.parsers.raise_parser_error
UnicodeDecodeError: 'ascii' codec can't decode byte 0x96 in position 25900: ordinal not in range(128)
----------------
2025-01-07_17:42:39  --->
Error level: ***ALERT!*** 
Message: Could not move files
<class 'Exception'>
NoneType: None
----------------
2025-01-07_17:42:39  --->
Error level: ***ALERT!*** 
Message: Could not move files
<class 'Exception'>
NoneType: None
----------------
2025-01-07_17:42:39  --->
Error level: ***ALERT!*** 
Message: Could not move files
<class 'Exception'>
NoneType: None
----------------
2025-01-07_17:43:07  --->
Error level: --Message-- 
Message: Zipfile contents for 2021
['crss2021csv/accident.csv', 'crss2021csv/cevent.csv', 'crss2021csv/crashrf.csv', 'crss2021csv/damage.csv', 'crss2021csv/distract.csv', 'crss2021csv/drimpair.csv', 'crss2021csv/driverrf.csv', 'crss2021csv/factor.csv', 'crss2021csv/maneuver.csv', 'crss2021csv/nmcrash.csv', 'crss2021csv/nmdistract.csv', 'crss2021csv/nmimpair.csv', 'crss2021csv/nmprior.csv', 'crss2021csv/parkwork.csv', 'crss2021csv/pbtype.csv', 'crss2021csv/person.csv', 'crss2021csv/personrf.csv', 'crss2021csv/pvehiclesf.csv', 'crss2021csv/safetyeq.csv', 'crss2021csv/vehicle.csv', 'crss2021csv/vehiclesf.csv', 'crss2021csv/vevent.csv', 'crss2021csv/violatn.csv', 'crss2021csv/vision.csv', 'crss2021csv/vpicdecode.csv', 'crss2021csv/vpictrailerdecode.csv', 'crss2021csv/vsoe.csv', 'crss2021csv/weather.csv']
NoneType: None
----------------
2025-01-07_17:43:10  --->
Error level: --Message-- 
Message: Raw cols accident.csv: 
['CASENUM', 'PSU', 'PSU_VAR', 'PSUSTRAT', 'REGION', 'REGIONNAME', 'URBANICITY', 'URBANICITYNAME', 'STRATUM', 'STRATUMNAME', 'PJ', 'WEIGHT', 'PEDS', 'PERNOTMVIT', 'VE_TOTAL', 'VE_FORMS', 'PVH_INVL', 'PERMVIT', 'MONTH', 'MONTHNAME', 'DAY_WEEK', 'DAY_WEEKNAME', 'WKDY_IM', 'WKDY_IMNAME', 'YEAR', 'YEARNAME', 'HOUR', 'HOURNAME', 'HOUR_IM', 'HOUR_IMNAME', 'MINUTE', 'MINUTENAME', 'MINUTE_IM', 'MINUTE_IMNAME', 'HARM_EV', 'HARM_EVNAME', 'EVENT1_IM', 'EVENT1_IMNAME', 'MAN_COLL', 'MAN_COLLNAME', 'MANCOL_IM', 'MANCOL_IMNAME', 'RELJCT1', 'RELJCT1NAME', 'RELJCT1_IM', 'RELJCT1_IMNAME', 'RELJCT2', 'RELJCT2NAME', 'RELJCT2_IM', 'RELJCT2_IMNAME', 'TYP_INT', 'TYP_INTNAME', 'REL_ROAD', 'REL_ROADNAME', 'WRK_ZONE', 'WRK_ZONENAME', 'LGT_COND', 'LGT_CONDNAME', 'LGTCON_IM', 'LGTCON_IMNAME', 'WEATHER', 'WEATHERNAME', 'WEATHR_IM', 'WEATHR_IMNAME', 'SCH_BUS', 'SCH_BUSNAME', 'INT_HWY', 'INT_HWYNAME', 'MAX_SEV', 'MAX_SEVNAME', 'MAXSEV_IM', 'MAXSEV_IMNAME', 'NUM_INJ', 'NUM_INJNAME', 'NO_INJ_IM', 'NO_INJ_IMNAME', 'ALCOHOL', 'ALCOHOLNAME', 'ALCHL_IM', 'ALCHL_IMNAME']
NoneType: None
----------------
2025-01-07_17:43:10  --->
Error level: --Message-- 
Message: Normalized cols accident.csv: 
['casenum', 'psu', 'psu_var', 'psustrat', 'region', 'regionname', 'urbanicity', 'urbanicityname', 'stratum', 'stratumname', 'pj', 'weight', 'peds', 'pernotmvit', 've_total', 've_forms', 'pvh_invl', 'permvit', 'month', 'monthname', 'day_week', 'day_weekname', 'wkdy_im', 'wkdy_imname', 'year', 'yearname', 'hour', 'hourname', 'hour_im', 'hour_imname', 'minute', 'minutename', 'minute_im', 'minute_imname', 'harm_ev', 'harm_evname', 'event1_im', 'event1_imname', 'man_coll', 'man_collname', 'mancol_im', 'mancol_imname', 'reljct1', 'reljct1name', 'reljct1_im', 'reljct1_imname', 'reljct2', 'reljct2name', 'reljct2_im', 'reljct2_imname', 'typ_int', 'typ_intname', 'rel_road', 'rel_roadname', 'wrk_zone', 'wrk_zonename', 'lgt_cond', 'lgt_condname', 'lgtcon_im', 'lgtcon_imname', 'weather', 'weathername', 'weathr_im', 'weathr_imname', 'sch_bus', 'sch_busname', 'int_hwy', 'int_hwyname', 'max_sev', 'max_sevname', 'maxsev_im', 'maxsev_imname', 'num_inj', 'num_injname', 'no_inj_im', 'no_inj_imname', 'alcohol', 'alcoholname', 'alchl_im', 'alchl_imname']
NoneType: None
----------------
2025-01-07_17:43:10  --->
Error level: --Message-- 
Message: Renamed cols accident.csv: 
['case_num', 'psu', 'psu_var', 'psustrat', 'region', 'regionname', 'urbancity', 'urbanicityname', 'stratum', 'stratumname', 'pj', 'weight', 'pedestrian', 'notin_veh', 'vehicles', 'moving', 'not_moving', 'occupants', 'month', 'monthname', 'day_week', 'day_weekname', 'wkdy_im', 'wkdy_imname', 'year', 'yearname', 'hour', 'hourname', 'hour_im', 'hour_imname', 'minute', 'minutename', 'minute_im', 'minute_imname', 'harm_ev', 'harm_evname', 'event1_im', 'event1_imname', 'collision', 'man_collname', 'mancol_im', 'mancol_imname', 'reljct1', 'reljct1name', 'reljct1_im', 'reljct1_imname', 'reljct2', 'reljct2name', 'related_junct', 'reljct2_imname', 'intersection', 'typ_intname', 'roadway', 'rel_roadname', 'workzone', 'wrk_zonename', 'lgt_cond', 'lgt_condname', 'lighting', 'lgtcon_imname', 'weather', 'weathername', 'weathr_im', 'weathr_imname', 'sch_bus', 'sch_busname', 'highway', 'int_hwyname', 'max_sev', 'max_sevname', 'max_injury', 'maxsev_imname', 'num_inj', 'num_injname', 'injuries', 'no_inj_imname', 'alcohol', 'alcoholname', 'alchl_im', 'alchl_imname']
NoneType: None
----------------
2025-01-07_17:44:47  --->
Error level: ***ALERT!*** 
Message: Could not move files
<class 'Exception'>
NoneType: None
----------------
2025-01-07_17:44:47  --->
Error level: ***ALERT!*** 
Message: Could not move files
<class 'Exception'>
NoneType: None
----------------
2025-01-07_17:44:47  --->
Error level: ***ALERT!*** 
Message: Could not move files
<class 'Exception'>
NoneType: None
----------------
2025-01-07_17:45:15  --->
Error level: --Message-- 
Message: Zipfile contents for 2022
['crss2022csv/accident.csv', 'crss2022csv/cevent.csv', 'crss2022csv/crashrf.csv', 'crss2022csv/damage.csv', 'crss2022csv/distract.csv', 'crss2022csv/drimpair.csv', 'crss2022csv/driverrf.csv', 'crss2022csv/factor.csv', 'crss2022csv/maneuver.csv', 'crss2022csv/nmcrash.csv', 'crss2022csv/nmdistract.csv', 'crss2022csv/nmimpair.csv', 'crss2022csv/nmprior.csv', 'crss2022csv/parkwork.csv', 'crss2022csv/pbtype.csv', 'crss2022csv/person.csv', 'crss2022csv/personrf.csv', 'crss2022csv/pvehiclesf.csv', 'crss2022csv/safetyeq.csv', 'crss2022csv/vehicle.csv', 'crss2022csv/vehiclesf.csv', 'crss2022csv/vevent.csv', 'crss2022csv/violatn.csv', 'crss2022csv/vision.csv', 'crss2022csv/vpicdecode.csv', 'crss2022csv/vpictrailerdecode.csv', 'crss2022csv/vsoe.csv', 'crss2022csv/weather.csv']
NoneType: None
----------------
2025-01-07_17:45:18  --->
Error level: --Message-- 
Message: Raw cols accident.csv: 
['CASENUM', 'PSU', 'PSU_VAR', 'PSUSTRAT', 'REGION', 'REGIONNAME', 'URBANICITY', 'URBANICITYNAME', 'STRATUM', 'STRATUMNAME', 'PJ', 'WEIGHT', 'PEDS', 'PERNOTMVIT', 'VE_TOTAL', 'VE_FORMS', 'PVH_INVL', 'PERMVIT', 'MONTH', 'MONTHNAME', 'DAY_WEEK', 'DAY_WEEKNAME', 'WKDY_IM', 'WKDY_IMNAME', 'YEAR', 'YEARNAME', 'HOUR', 'HOURNAME', 'HOUR_IM', 'HOUR_IMNAME', 'MINUTE', 'MINUTENAME', 'MINUTE_IM', 'MINUTE_IMNAME', 'HARM_EV', 'HARM_EVNAME', 'EVENT1_IM', 'EVENT1_IMNAME', 'MAN_COLL', 'MAN_COLLNAME', 'MANCOL_IM', 'MANCOL_IMNAME', 'RELJCT1', 'RELJCT1NAME', 'RELJCT1_IM', 'RELJCT1_IMNAME', 'RELJCT2', 'RELJCT2NAME', 'RELJCT2_IM', 'RELJCT2_IMNAME', 'TYP_INT', 'TYP_INTNAME', 'REL_ROAD', 'REL_ROADNAME', 'WRK_ZONE', 'WRK_ZONENAME', 'LGT_COND', 'LGT_CONDNAME', 'LGTCON_IM', 'LGTCON_IMNAME', 'WEATHER', 'WEATHERNAME', 'WEATHR_IM', 'WEATHR_IMNAME', 'SCH_BUS', 'SCH_BUSNAME', 'INT_HWY', 'INT_HWYNAME', 'MAX_SEV', 'MAX_SEVNAME', 'MAXSEV_IM', 'MAXSEV_IMNAME', 'NUM_INJ', 'NUM_INJNAME', 'NO_INJ_IM', 'NO_INJ_IMNAME', 'ALCOHOL', 'ALCOHOLNAME', 'ALCHL_IM', 'ALCHL_IMNAME']
NoneType: None
----------------
2025-01-07_17:45:18  --->
Error level: --Message-- 
Message: Normalized cols accident.csv: 
['casenum', 'psu', 'psu_var', 'psustrat', 'region', 'regionname', 'urbanicity', 'urbanicityname', 'stratum', 'stratumname', 'pj', 'weight', 'peds', 'pernotmvit', 've_total', 've_forms', 'pvh_invl', 'permvit', 'month', 'monthname', 'day_week', 'day_weekname', 'wkdy_im', 'wkdy_imname', 'year', 'yearname', 'hour', 'hourname', 'hour_im', 'hour_imname', 'minute', 'minutename', 'minute_im', 'minute_imname', 'harm_ev', 'harm_evname', 'event1_im', 'event1_imname', 'man_coll', 'man_collname', 'mancol_im', 'mancol_imname', 'reljct1', 'reljct1name', 'reljct1_im', 'reljct1_imname', 'reljct2', 'reljct2name', 'reljct2_im', 'reljct2_imname', 'typ_int', 'typ_intname', 'rel_road', 'rel_roadname', 'wrk_zone', 'wrk_zonename', 'lgt_cond', 'lgt_condname', 'lgtcon_im', 'lgtcon_imname', 'weather', 'weathername', 'weathr_im', 'weathr_imname', 'sch_bus', 'sch_busname', 'int_hwy', 'int_hwyname', 'max_sev', 'max_sevname', 'maxsev_im', 'maxsev_imname', 'num_inj', 'num_injname', 'no_inj_im', 'no_inj_imname', 'alcohol', 'alcoholname', 'alchl_im', 'alchl_imname']
NoneType: None
----------------
2025-01-07_17:45:18  --->
Error level: --Message-- 
Message: Renamed cols accident.csv: 
['case_num', 'psu', 'psu_var', 'psustrat', 'region', 'regionname', 'urbancity', 'urbanicityname', 'stratum', 'stratumname', 'pj', 'weight', 'pedestrian', 'notin_veh', 'vehicles', 'moving', 'not_moving', 'occupants', 'month', 'monthname', 'day_week', 'day_weekname', 'wkdy_im', 'wkdy_imname', 'year', 'yearname', 'hour', 'hourname', 'hour_im', 'hour_imname', 'minute', 'minutename', 'minute_im', 'minute_imname', 'harm_ev', 'harm_evname', 'event1_im', 'event1_imname', 'collision', 'man_collname', 'mancol_im', 'mancol_imname', 'reljct1', 'reljct1name', 'reljct1_im', 'reljct1_imname', 'reljct2', 'reljct2name', 'related_junct', 'reljct2_imname', 'intersection', 'typ_intname', 'roadway', 'rel_roadname', 'workzone', 'wrk_zonename', 'lgt_cond', 'lgt_condname', 'lighting', 'lgtcon_imname', 'weather', 'weathername', 'weathr_im', 'weathr_imname', 'sch_bus', 'sch_busname', 'highway', 'int_hwyname', 'max_sev', 'max_sevname', 'max_injury', 'maxsev_imname', 'num_inj', 'num_injname', 'injuries', 'no_inj_imname', 'alcohol', 'alcoholname', 'alchl_im', 'alchl_imname']
NoneType: None
----------------
2025-01-07_17:46:39  --->
Error level: ***ALERT!*** 
Message: Could not move files
<class 'Exception'>
NoneType: None
----------------
2025-01-07_17:46:39  --->
Error level: ***ALERT!*** 
Message: Could not move files
<class 'Exception'>
NoneType: None
----------------
2025-01-07_17:46:39  --->
Error level: ***ALERT!*** 
Message: Could not move files
<class 'Exception'>
NoneType: None
